<?xml version="1.0" ?>
<!-- =================================================================================== -->
<!-- |    This document was autogenerated by xacro from opy_v05.xacro                  | -->
<!-- |    EDITING THIS FILE BY HAND IS NOT RECOMMENDED                                 | -->
<!-- =================================================================================== -->
<!--
 
This is a xacro file used to describe the mechanical properties of a quadruped.
 
Xacro is an XML language based on URDF. It has the capability of running macros. Such as taking variables and writing functions.
Xacro can be converted to a straightforward URDF file pretty easily. So it is advantageous to use.
 
This file can be used as a template for future changes in the robot.
This file alone does not work since it refers to other Xacro files (quadruped_macros.xacro) and functions inside them. 
 
The document explains each property with comments (green) above them.
 
As a rule of thumb, in vscode turquoise indicates variable name and orange indicates the value of the variable.
Edit orange values only.
 
-->
<robot name="opy_v05">
  <!--
- custom tags. please enter the desired values if available
gear ratios - no units
motorTauMax: maximum torque the motor can aply. Nm
batteryV: Battery Voltage, Volts
motorKT: from motor sheet
motorR: Ohms
rotorRadius: and rotorHeight in meters
RotorMass: in kg
-->
  <custom abadGearRatio="1" batteryV="24" body_height="5" hipGearRatio="1" kneeGearRatio="1" motorKT="0.095" motorR="0.272" motorTauMax="25" rotorHeight="0.0502" rotorMass="0.521" rotorRadius="0.083"/>
  <!-- robot name -->
  <!-- This parameter is only important if use_mesh_file is set to 0. Otherwise this parameter will be assumed to equal 1 anyways.
 
  If you use mesh files, you may still want to use a simple ball as your feet instead of a complex sphere.
  This is beneficial if you are planning on using this URDF in simulation programs.
  For example MuJoCo solves contact geometries much better if you use a sphere instead of a mesh file for feet. 
  If the realistic visuatization of the robot's feet is important for you, use 0.
  To use this URDF in simulation, it is recommended to use 1. -->
  <!-- [kg] -->
  <!--[N] -->
  <!-- _______________________________________________________________________________ -->
  <!-- The below values will be filled for FRONT LEFT - FL - LEG 2 of the robot -->
  <!-- [m] -->
  <!-- [m] -->
  <!-- [m] -->
  <!-- [ixx ixy ixz iyy iyz izz] -->
  <!-- [m] -->
  <!-- [m] -->
  <!-- [ixx ixy ixz iyy iyz izz] -->
  <!-- [m] -->
  <!-- [m] -->
  <!-- [ixx ixy ixz iyy iyz izz] -->
  <!-- [m] -->
  <!-- [m] -->
  <!-- [ixx ixy ixz iyy iyz izz] -->
  <!-- _______________________________________________________________________________ -->
  <!-- directory to file -->
  <!-- [kg] -->
  <!-- _______________________________________________________________________________ -->
  <!-- FILL THE BELOW VALUES IF  -->
  <!-- use_mesh_file = 0  OR  use_simple_inertia = 1 -->
  <!-- [m] -->
  <!-- [m] -->
  <!-- [m] -->
  <!-- [m] -->
  <!-- [m] -->
  <!-- NOT USED ANYMORE; WILL BE DELETED  -->
  <!-- <xacro:property name="abad_x_offset" value="0.07675" />
  <xacro:property name="knee_y_offset" value="0.08024" /> -->
  <!-- ________________________________DONT EDIT BELOW THIS LINE_______________________________________________ -->
  <material name="gray">
    <color rgba="0.5 0.5 0.5 1"/>
  </material>
  <material name="green">
    <color rgba="0 0.4 0 1"/>
  </material>
  <material name="black">
    <color rgba="0 0 0 0.9"/>
  </material>
  <link name="opy_v05/base_link"> </link>
  <joint name="opy_v05/base_joint" type="revolute">
    <origin rpy="0 0 0" xyz="0 0 0"/>
    <parent link="opy_v05/base_link"/>
    <child link="opy_v05/base_link_inertia"/>
  </joint>
  <link name="opy_v05/base_link_inertia">
    <inertial>
      <origin rpy="0 0 0" xyz="0.0 0.0 0.0"/>
      <mass value="14.2"/>
      <!-- The base is symmetrical. -->
      <inertia ixx="0.127732" ixy="-0.00297058" ixz="0.00147725" iyy="0.251312" iyz="0.00112127" izz="0.288919"/>
    </inertial>
    <visual>
      <origin rpy="0 0 0" xyz="0 0 0"/>
      <geometry>
        <mesh filename="package://opy-highlevel/meshes/opy_v05/GOVDE.stl"/>
      </geometry>
      <material name="gray"/>
    </visual>
    <collision>
      <origin rpy="0 0 0" xyz="0 0 0"/>
      <geometry>
        <mesh filename="package://opy-highlevel/meshes/opy_v05/GOVDE.stl"/>
      </geometry>
    </collision>
  </link>
  <joint name="opy_v05/abad_1_joint" type="revolute">
    <limit effort="1e3" lower="-3.141592653589793" upper="3.141592653589793" velocity="1e3"/>
    <dynamics damping="0.03" friction="0.05"/>
    <!-- abad_joint_origin -->
    <origin rpy="0 0 0" xyz="0.2238953 -0.0655252 0"/>
    <axis xyz="1 0 0"/>
    <parent link="opy_v05/base_link"/>
    <child link="opy_v05/abad_1"/>
  </joint>
  <link name="opy_v05/abad_1">
    <inertial>
      <!-- abad_link_origin -->
      <origin rpy="0 0 0" xyz="0.0178557 -0.0014481 0.0001213"/>
      <mass value="1.2834"/>
      <!-- [kg] -->
      <!-- abad_inertia_at_com -->
      <inertia ixx="0.00096607" ixy="-5.54985e-05" ixz="-7.4765e-06" iyy="0.00316857" iyz="-4.522e-07" izz="0.00294342"/>
    </inertial>
    <visual>
      <!-- ${dir_sign[leg-1]*0.785398+0.785398} -->
      <origin rpy="0 0 0" xyz="0.0195 0 0"/>
      <geometry>
        <mesh filename="package://opy-highlevel/meshes/opy_v05/ABDUCTION_1.stl"/>
      </geometry>
      <material name="green"/>
    </visual>
    <collision>
      <origin rpy="-3.14 0.0 0" xyz="0 0 0"/>
      <geometry>
        <mesh filename="package://opy-highlevel/meshes/opy_v05/ABDUCTION.stl"/>
      </geometry>
    </collision>
  </link>
  <joint name="opy_v05/hip_1_joint" type="revolute">
    <limit effort="1e3" lower="-3.141592653589793" upper="3.141592653589793" velocity="1e3"/>
    <dynamics damping="0.03" friction="0.05"/>
    <!-- hip_joint_origin -->
    <origin rpy="0 0 3.14" xyz="0.0644992 -0.025 0"/>
    <axis xyz="0 1 0"/>
    <parent link="opy_v05/abad_1"/>
    <child link="opy_v05/hip_1"/>
  </joint>
  <link name="opy_v05/hip_1">
    <inertial>
      <!-- hip_link_origin -->
      <origin rpy="0 0 0" xyz="0.0052933 0.0512201 -0.0389842"/>
      <mass value="2.3239"/>
      <inertia ixx="0.0196654" ixy="0.000348068" ixz="-0.00130155" iyy="0.0201328" iyz="-0.0025115" izz="0.00482801"/>
    </inertial>
    <visual>
      <origin rpy="0 0 0.0" xyz="0 0 0"/>
      <geometry>
        <mesh filename="package://opy-highlevel/meshes/opy_v05/HIP_R.stl"/>
      </geometry>
      <material name="green"/>
    </visual>
    <collision>
      <origin rpy="0 0 0.0" xyz="0 0 0"/>
      <geometry>
        <mesh filename="package://opy-highlevel/meshes/opy_v05/HIP_R.stl"/>
      </geometry>
    </collision>
  </link>
  <joint name="opy_v05/knee_1_joint" type="revolute">
    <!-- knee_joint_origin -->
    <origin rpy="0 0 0" xyz="0.0 0.07885 -0.27"/>
    <limit effort="1e3" lower="-3.141592653589793" upper="3.141592653589793" velocity="1e3"/>
    <dynamics damping="0.03" friction="0.05"/>
    <axis xyz="0 1 0"/>
    <parent link="opy_v05/hip_1"/>
    <child link="opy_v05/knee_1"/>
  </joint>
  <link name="opy_v05/knee_1">
    <inertial>
      <origin rpy="0 0 0" xyz="-0.0132476 8.24e-05 -0.183019"/>
      <mass value="0.3966"/>
      <inertia ixx="0.00436796" ixy="3.12e-08" ixz="8.37378e-05" iyy="0.00442188" iyz="-2.4768e-06" izz="0.000171289"/>
    </inertial>
    <visual>
      <origin rpy="0 0 0.0" xyz="0 0 0"/>
      <geometry>
        <mesh filename="package://opy-highlevel/meshes/opy_v05/KNEE.stl"/>
      </geometry>
      <material name="green"/>
    </visual>
    <collision>
      <origin rpy="0 0 0.0" xyz="0 0 0"/>
      <geometry>
        <mesh filename="package://opy-highlevel/meshes/opy_v05/KNEE.stl"/>
      </geometry>
    </collision>
  </link>
  <joint name="opy_v05/foot_1_joint" type="fixed">
    <!-- foot_joint_origin -->
    <origin rpy="0 0 0" xyz="0.0 -0.0 -0.2883978"/>
    <parent link="opy_v05/knee_1"/>
    <child link="opy_v05/foot_1"/>
  </joint>
  <link name="opy_v05/foot_1">
    <inertial>
      <!-- foot_link_origin -->
      <origin rpy="0 0 0" xyz="0.0012849 -8.24e-05 -0.002989"/>
      <mass value="0.1737"/>
      <!-- foot_inertia_at_com -->
      <inertia ixx="2.91738e-05" ixy="1.4e-08" ixz="3.1938e-06" iyy="3.41281e-05" iyz="-1.67e-08" izz="3.48311e-05"/>
    </inertial>
    <visual>
      <origin rpy="0 0 0" xyz="0 0 0"/>
      <geometry>
        <mesh filename="package://opy-highlevel/meshes/opy_v05/FOOT.stl"/>
      </geometry>
      <material name="black"/>
    </visual>
    <collision>
      <origin rpy="0 0 0" xyz="0 0 0"/>
      <geometry>
        <sphere radius="0.02"/>
      </geometry>
    </collision>
  </link>
  <joint name="opy_v05/abad_2_joint" type="revolute">
    <limit effort="1e3" lower="-3.141592653589793" upper="3.141592653589793" velocity="1e3"/>
    <dynamics damping="0.03" friction="0.05"/>
    <!-- abad_joint_origin -->
    <origin rpy="0 0 0" xyz="0.2238953 0.0655252 0"/>
    <axis xyz="1 0 0"/>
    <parent link="opy_v05/base_link"/>
    <child link="opy_v05/abad_2"/>
  </joint>
  <link name="opy_v05/abad_2">
    <inertial>
      <!-- abad_link_origin -->
      <origin rpy="0 0 0" xyz="0.0178557 0.0014481 0.0001213"/>
      <mass value="1.2834"/>
      <!-- [kg] -->
      <!-- abad_inertia_at_com -->
      <inertia ixx="0.00096607" ixy="5.54985e-05" ixz="-7.4765e-06" iyy="0.00316857" iyz="4.522e-07" izz="0.00294342"/>
    </inertial>
    <visual>
      <!-- ${dir_sign[leg-1]*0.785398+0.785398} -->
      <origin rpy="0 0 0" xyz="0.0195 0 0"/>
      <geometry>
        <mesh filename="package://opy-highlevel/meshes/opy_v05/ABDUCTION_2.stl"/>
      </geometry>
      <material name="green"/>
    </visual>
    <collision>
      <origin rpy="0.0 0.0 0" xyz="0 0 0"/>
      <geometry>
        <mesh filename="package://opy-highlevel/meshes/opy_v05/ABDUCTION.stl"/>
      </geometry>
    </collision>
  </link>
  <joint name="opy_v05/hip_2_joint" type="revolute">
    <limit effort="1e3" lower="-3.141592653589793" upper="3.141592653589793" velocity="1e3"/>
    <dynamics damping="0.03" friction="0.05"/>
    <!-- hip_joint_origin -->
    <origin rpy="0 0 3.14" xyz="0.0644992 0.025 0"/>
    <axis xyz="0 1 0"/>
    <parent link="opy_v05/abad_2"/>
    <child link="opy_v05/hip_2"/>
  </joint>
  <link name="opy_v05/hip_2">
    <inertial>
      <!-- hip_link_origin -->
      <origin rpy="0 0 0" xyz="0.0052933 -0.0512201 -0.0389842"/>
      <mass value="2.3239"/>
      <inertia ixx="0.0196654" ixy="-0.000348068" ixz="-0.00130155" iyy="0.0201328" iyz="0.0025115" izz="0.00482801"/>
    </inertial>
    <visual>
      <origin rpy="0 0 0.0" xyz="0 0 0"/>
      <geometry>
        <mesh filename="package://opy-highlevel/meshes/opy_v05/HIP_L.stl"/>
      </geometry>
      <material name="green"/>
    </visual>
    <collision>
      <origin rpy="0 0 0.0" xyz="0 0 0"/>
      <geometry>
        <mesh filename="package://opy-highlevel/meshes/opy_v05/HIP_L.stl"/>
      </geometry>
    </collision>
  </link>
  <joint name="opy_v05/knee_2_joint" type="revolute">
    <!-- knee_joint_origin -->
    <origin rpy="0 0 0" xyz="0.0 -0.07885 -0.27"/>
    <limit effort="1e3" lower="-3.141592653589793" upper="3.141592653589793" velocity="1e3"/>
    <dynamics damping="0.03" friction="0.05"/>
    <axis xyz="0 1 0"/>
    <parent link="opy_v05/hip_2"/>
    <child link="opy_v05/knee_2"/>
  </joint>
  <link name="opy_v05/knee_2">
    <inertial>
    <!-- knee_joint_hata yer ve ağırlık düzeltilecek!!!!!!!!! -->
      <origin rpy="0 0 0" xyz="-0.0132476 -8.24e-05 -0.183019"/>
      <mass value="0.3966"/>
      <inertia ixx="0.00436796" ixy="-3.12e-08" ixz="8.37378e-05" iyy="0.00442188" iyz="2.4768e-06" izz="0.000171289"/>
    </inertial>
    <visual>
      <origin rpy="0 0 0.0" xyz="0 0 0"/>
      <geometry>
        <mesh filename="package://opy-highlevel/meshes/opy_v05/KNEE.stl"/>
      </geometry>
      <material name="green"/>
    </visual>
    <collision>
      <origin rpy="0 0 0.0" xyz="0 0 0"/>
      <geometry>
        <mesh filename="package://opy-highlevel/meshes/opy_v05/KNEE.stl"/>
      </geometry>
    </collision>
  </link>
  <joint name="opy_v05/foot_2_joint" type="fixed">
    <!-- foot_joint_origin -->
    <origin rpy="0 0 0" xyz="0.0 0.0 -0.2883978"/>
    <parent link="opy_v05/knee_2"/>
    <child link="opy_v05/foot_2"/>
  </joint>
  <link name="opy_v05/foot_2">
    <inertial>
      <!-- foot_link_origin -->
      <origin rpy="0 0 0" xyz="0.0012849 8.24e-05 -0.002989"/>
      <mass value="0.1737"/>
      <!-- foot_inertia_at_com -->
      <inertia ixx="2.91738e-05" ixy="-1.4e-08" ixz="3.1938e-06" iyy="3.41281e-05" iyz="1.67e-08" izz="3.48311e-05"/>
    </inertial>
    <visual>
      <origin rpy="0 0 0" xyz="0 0 0"/>
      <geometry>
        <mesh filename="package://opy-highlevel/meshes/opy_v05/FOOT.stl"/>
      </geometry>
      <material name="black"/>
    </visual>
    <collision>
      <origin rpy="0 0 0" xyz="0 0 0"/>
      <geometry>
        <sphere radius="0.02"/>
      </geometry>
    </collision>
  </link>
  <joint name="opy_v05/abad_3_joint" type="revolute">
    <limit effort="1e3" lower="-3.141592653589793" upper="3.141592653589793" velocity="1e3"/>
    <dynamics damping="0.03" friction="0.05"/>
    <!-- abad_joint_origin -->
    <origin rpy="0 0 0" xyz="-0.2238953 -0.0655252 0"/>
    <axis xyz="1 0 0"/>
    <parent link="opy_v05/base_link"/>
    <child link="opy_v05/abad_3"/>
  </joint>
  <link name="opy_v05/abad_3">
    <inertial>
      <!-- abad_link_origin -->
      <origin rpy="0 0 0" xyz="-0.0178557 -0.0014481 0.0001213"/>
      <mass value="1.2834"/>
      <!-- [kg] -->
      <!-- abad_inertia_at_com -->
      <inertia ixx="0.00096607" ixy="5.54985e-05" ixz="7.4765e-06" iyy="0.00316857" iyz="-4.522e-07" izz="0.00294342"/>
    </inertial>
    <visual>
      <!-- ${dir_sign[leg-1]*0.785398+0.785398} -->
      <origin rpy="0 0 0" xyz="-0.0195 0 0"/>
      <geometry>
        <mesh filename="package://opy-highlevel/meshes/opy_v05/ABDUCTION_3.stl"/>
      </geometry>
      <material name="green"/>
    </visual>
    <collision>
      <origin rpy="-3.14 -3.14 0" xyz="0 0 0"/>
      <geometry>
        <mesh filename="package://opy-highlevel/meshes/opy_v05/ABDUCTION.stl"/>
      </geometry>
    </collision>
  </link>
  <joint name="opy_v05/hip_3_joint" type="revolute">
    <limit effort="1e3" lower="-3.141592653589793" upper="3.141592653589793" velocity="1e3"/>
    <dynamics damping="0.03" friction="0.05"/>
    <!-- hip_joint_origin -->
    <origin rpy="0 0 3.14" xyz="-0.0644992 -0.025 0"/>
    <axis xyz="0 1 0"/>
    <parent link="opy_v05/abad_3"/>
    <child link="opy_v05/hip_3"/>
  </joint>
  <link name="opy_v05/hip_3">
    <inertial>
      <!-- hip_link_origin -->
      <origin rpy="0 0 0" xyz="0.0052933 0.0512201 -0.0389842"/>
      <mass value="2.3239"/>
      <inertia ixx="0.0196654" ixy="-0.000348068" ixz="0.00130155" iyy="0.0201328" iyz="-0.0025115" izz="0.00482801"/>
    </inertial>
    <visual>
      <origin rpy="0 0 0.0" xyz="0 0 0"/>
      <geometry>
        <mesh filename="package://opy-highlevel/meshes/opy_v05/HIP_R.stl"/>
      </geometry>
      <material name="green"/>
    </visual>
    <collision>
      <origin rpy="0 0 0.0" xyz="0 0 0"/>
      <geometry>
        <mesh filename="package://opy-highlevel/meshes/opy_v05/HIP_R.stl"/>
      </geometry>
    </collision>
  </link>
  <joint name="opy_v05/knee_3_joint" type="revolute">
    <!-- knee_joint_origin -->
    <origin rpy="0 0 0" xyz="0.0 0.07885 -0.27"/>
    <limit effort="1e3" lower="-3.141592653589793" upper="3.141592653589793" velocity="1e3"/>
    <dynamics damping="0.03" friction="0.05"/>
    <axis xyz="0 1 0"/>
    <parent link="opy_v05/hip_3"/>
    <child link="opy_v05/knee_3"/>
  </joint>
  <link name="opy_v05/knee_3">
    <inertial>
      <origin rpy="0 0 0" xyz="-0.0132476 8.24e-05 -0.183019"/>
      <mass value="0.3966"/>
      <inertia ixx="0.00436796" ixy="-3.12e-08" ixz="-8.37378e-05" iyy="0.00442188" iyz="-2.4768e-06" izz="0.000171289"/>
    </inertial>
    <visual>
      <origin rpy="0 0 0.0" xyz="0 0 0"/>
      <geometry>
        <mesh filename="package://opy-highlevel/meshes/opy_v05/KNEE.stl"/>
      </geometry>
      <material name="green"/>
    </visual>
    <collision>
      <origin rpy="0 0 0.0" xyz="0 0 0"/>
      <geometry>
        <mesh filename="package://opy-highlevel/meshes/opy_v05/KNEE.stl"/>
      </geometry>
    </collision>
  </link>
  <joint name="opy_v05/foot_3_joint" type="fixed">
    <!-- foot_joint_origin -->
    <origin rpy="0 0 0" xyz="0.0 -0.0 -0.2883978"/>
    <parent link="opy_v05/knee_3"/>
    <child link="opy_v05/foot_3"/>
  </joint>
  <link name="opy_v05/foot_3">
    <inertial>
      <!-- foot_link_origin -->
      <origin rpy="0 0 0" xyz="0.0012849 -8.24e-05 -0.002989"/>
      <mass value="0.1737"/>
      <!-- foot_inertia_at_com -->
      <inertia ixx="2.91738e-05" ixy="-1.4e-08" ixz="-3.1938e-06" iyy="3.41281e-05" iyz="-1.67e-08" izz="3.48311e-05"/>
    </inertial>
    <visual>
      <origin rpy="0 0 0" xyz="0 0 0"/>
      <geometry>
        <mesh filename="package://opy-highlevel/meshes/opy_v05/FOOT.stl"/>
      </geometry>
      <material name="black"/>
    </visual>
    <collision>
      <origin rpy="0 0 0" xyz="0 0 0"/>
      <geometry>
        <sphere radius="0.02"/>
      </geometry>
    </collision>
  </link>
  <joint name="opy_v05/abad_4_joint" type="revolute">
    <limit effort="1e3" lower="-3.141592653589793" upper="3.141592653589793" velocity="1e3"/>
    <dynamics damping="0.03" friction="0.05"/>
    <!-- abad_joint_origin -->
    <origin rpy="0 0 0" xyz="-0.2238953 0.0655252 0"/>
    <axis xyz="1 0 0"/>
    <parent link="opy_v05/base_link"/>
    <child link="opy_v05/abad_4"/>
  </joint>
  <link name="opy_v05/abad_4">
    <inertial>
      <!-- abad_link_origin -->
      <origin rpy="0 0 0" xyz="-0.0178557 0.0014481 0.0001213"/>
      <mass value="1.2834"/>
      <!-- [kg] -->
      <!-- abad_inertia_at_com -->
      <inertia ixx="0.00096607" ixy="-5.54985e-05" ixz="7.4765e-06" iyy="0.00316857" iyz="4.522e-07" izz="0.00294342"/>
    </inertial>
    <visual>
      <!-- ${dir_sign[leg-1]*0.785398+0.785398} -->
      <origin rpy="0 0 0" xyz="-0.0195 0 0"/>
      <geometry>
        <mesh filename="package://opy-highlevel/meshes/opy_v05/ABDUCTION_4.stl"/>
      </geometry>
      <material name="green"/>
    </visual>
    <collision>
      <origin rpy="0.0 -3.14 0" xyz="0 0 0"/>
      <geometry>
        <mesh filename="package://opy-highlevel/meshes/opy_v05/ABDUCTION.stl"/>
      </geometry>
    </collision>
  </link>
  <joint name="opy_v05/hip_4_joint" type="revolute">
    <limit effort="1e3" lower="-3.141592653589793" upper="3.141592653589793" velocity="1e3"/>
    <dynamics damping="0.03" friction="0.05"/>
    <!-- hip_joint_origin -->
    <origin rpy="0 0 3.14" xyz="-0.0644992 0.025 0"/>
    <axis xyz="0 1 0"/>
    <parent link="opy_v05/abad_4"/>
    <child link="opy_v05/hip_4"/>
  </joint>
  <link name="opy_v05/hip_4">
    <inertial>
      <!-- hip_link_origin -->
      <origin rpy="0 0 0" xyz="0.0052933 -0.0512201 -0.0389842"/>
      <mass value="2.3239"/>
      <inertia ixx="0.0196654" ixy="0.000348068" ixz="0.00130155" iyy="0.0201328" iyz="0.0025115" izz="0.00482801"/>
    </inertial>
    <visual>
      <origin rpy="0 0 0.0" xyz="0 0 0"/>
      <geometry>
        <mesh filename="package://opy-highlevel/meshes/opy_v05/HIP_L.stl"/>
      </geometry>
      <material name="green"/>
    </visual>
    <collision>
      <origin rpy="0 0 0.0" xyz="0 0 0"/>
      <geometry>
        <mesh filename="package://opy-highlevel/meshes/opy_v05/HIP_L.stl"/>
      </geometry>
    </collision>
  </link>
  <joint name="opy_v05/knee_4_joint" type="revolute">
    <!-- knee_joint_origin -->
    <origin rpy="0 0 0" xyz="0.0 -0.07885 -0.27"/>
    <limit effort="1e3" lower="-3.141592653589793" upper="3.141592653589793" velocity="1e3"/>
    <dynamics damping="0.03" friction="0.05"/>
    <axis xyz="0 1 0"/>
    <parent link="opy_v05/hip_4"/>
    <child link="opy_v05/knee_4"/>
  </joint>
  <link name="opy_v05/knee_4">
    <inertial>
      <origin rpy="0 0 0" xyz="-0.0132476 -8.24e-05 -0.183019"/>
      <mass value="0.3966"/>
      <inertia ixx="0.00436796" ixy="3.12e-08" ixz="-8.37378e-05" iyy="0.00442188" iyz="2.4768e-06" izz="0.000171289"/>
    </inertial>
    <visual>
      <origin rpy="0 0 0.0" xyz="0 0 0"/>
      <geometry>
        <mesh filename="package://opy-highlevel/meshes/opy_v05/KNEE.stl"/>
      </geometry>
      <material name="green"/>
    </visual>
    <collision>
      <origin rpy="0 0 0.0" xyz="0 0 0"/>
      <geometry>
        <mesh filename="package://opy-highlevel/meshes/opy_v05/KNEE.stl"/>
      </geometry>
    </collision>
  </link>
  <joint name="opy_v05/foot_4_joint" type="fixed">
    <!-- foot_joint_origin -->
    <origin rpy="0 0 0" xyz="0.0 0.0 -0.2883978"/>
    <parent link="opy_v05/knee_4"/>
    <child link="opy_v05/foot_4"/>
  </joint>
  <link name="opy_v05/foot_4">
    <inertial>
      <!-- foot_link_origin -->
      <origin rpy="0 0 0" xyz="0.0012849 8.24e-05 -0.002989"/>
      <mass value="0.1737"/>
      <!-- foot_inertia_at_com -->
      <inertia ixx="2.91738e-05" ixy="1.4e-08" ixz="-3.1938e-06" iyy="3.41281e-05" iyz="1.67e-08" izz="3.48311e-05"/>
    </inertial>
    <visual>
      <origin rpy="0 0 0" xyz="0 0 0"/>
      <geometry>
        <mesh filename="package://opy-highlevel/meshes/opy_v05/FOOT.stl"/>
      </geometry>
      <material name="black"/>
    </visual>
    <collision>
      <origin rpy="0 0 0" xyz="0 0 0"/>
      <geometry>
        <sphere radius="0.02"/>
      </geometry>
    </collision>
  </link>
</robot>
