<mujoco model="opy_v05">
  <compiler angle="radian" meshdir="../opy_v05/meshes/" autolimits="true"/>
  <statistic meansize="0.233652" extent="1.00882" center="0 0 -0.175588"/>
    <asset>
    <!-- <hfield name="hmap" file="my_output_image.png" size="3 3 0.3 0.07"/> -->
    <texture type="skybox" builtin="gradient" rgb1="0.3 0.5 0.7" rgb2="0 0 0" width="32" height="192"/>
    <texture type="cube" name="body" builtin="flat" mark="cross" rgb1="0.8 0.6 0.4" rgb2="0.8 0.6 0.4" markrgb="1 1 1" width="127" height="762"/>
    <texture type="2d" name="grid" builtin="checker" rgb1="0.1 0.2 0.3" rgb2="0.2 0.3 0.4" width="512" height="512"/>
    <material name="body" texture="body" texuniform="true" rgba="0.8 0.6 0.4 1"/>
    <material name="grid" texture="grid" texuniform="true" reflectance="0.2"/>
    <mesh name="slope" file="slope.stl" scale = "1 1 1"/>
    <mesh name="GOVDE" file="GOVDE.stl"/>
    <mesh name="ABDUCTION" file="ABDUCTION.stl"/>
    <mesh name="HIP_L" file="HIP_L.stl"/>
    <mesh name="KNEE" file="KNEE.stl"/>
    <mesh name="FOOT" file="FOOT.stl"/>
    <mesh name="HIP_R" file="HIP_R.stl"/>
  </asset>
  <worldbody>
    <geom name="floor" size="0 0 1" type="plane" material="grid" />
   
    <light name="spotlight" target="opy_v05/base_link_inertia" pos="0 -6 6" dir="0 0 -1" cutoff="30" diffuse="0.8 0.8 0.8" mode="targetbodycom"/>

    <body name="opy_v05/base_link_inertia" pos="0 0 0.12">
      <site name="sensorsurf" pos="0 0 0" size=".005 .005 .005" rgba="0.5 0.5 0.5 1" euler="0 0 0"/>

      <joint name="opy_v05/base_joint" pos="0 0 0" type="free"/>

,

      <inertial pos="0 0 0" quat="0.00167939 0.710147 0.0188142 0.7038" mass="14.2" diaginertia="0.288964 0.251352 0.127647"/>
      <geom type="mesh" mesh="GOVDE"/>

    <body name="opy_v05/abad_1" pos="0.223895 -0.0655252 0">
      <inertial pos="0.0178557 -0.0014481 0.0001213" quat="0.494895 0.492437 0.505583 0.506923" mass="1.2834" diaginertia="0.00316997 0.00294345 0.000964644"/>
      <joint name="opy_v05/abad_1_joint" pos="0 0 0" axis="1 0 0" limited="true" range="-3.14159 3.14159" damping="0.03" frictionloss="0.05"/>
      <geom quat="0.000796327 -1 0 0" type="mesh" rgba="0 0.4 0 1" mesh="ABDUCTION"/>
      <body name="opy_v05/hip_1" pos="0.0644992 -0.025 0" quat="0.000796327 0 0 1">
        <inertial pos="0.0052933 0.0512201 -0.0389842" quat="0.853011 -0.045741 0.0745125 0.514518" mass="2.3239" diaginertia="0.0208187 0.0194799 0.00432761"/>
        <joint name="opy_v05/hip_1_joint" pos="0 0 0" axis="0 1 0" limited="true" range="-3.14159 3.14159" damping="0.03" frictionloss="0.05"/>
        <geom type="mesh" rgba="0 0.4 0 1" mesh="HIP_R"/>
        <body name="opy_v05/knee_1" pos="0 0.07885 -0.27">
          <inertial pos="-0.00882134 3.22058e-05 -0.216025" quat="0.707418 -0.0177669 -0.0172127 0.706362" mass="0.5703" diaginertia="0.00590009 0.00582943 0.000217907"/>
          <joint name="opy_v05/knee_1_joint" pos="0 0 0" axis="0 1 0" limited="true" range="-3.14159 3.14159" damping="0.03" frictionloss="0.05"/>
          <geom type="mesh" rgba="0 0.4 0 1" mesh="KNEE"/>
          <geom name="ROBOT_FOOT_1" size="0.02" pos="0 0 -0.288398" rgba="0 0 0 0.9"/>
        </body>
      </body>
    </body>
    <body name="opy_v05/abad_2" pos="0.223895 0.0655252 0">
      <inertial pos="0.0178557 0.0014481 0.0001213" quat="0.506923 0.505583 0.492437 0.494895" mass="1.2834" diaginertia="0.00316997 0.00294345 0.000964644"/>
      <joint name="opy_v05/abad_2_joint" pos="0 0 0" axis="1 0 0" limited="true" range="-3.14159 3.14159" damping="0.03" frictionloss="0.05"/>
      <geom type="mesh" rgba="0 0.4 0 1" mesh="ABDUCTION"/>
      <body name="opy_v05/hip_2" pos="0.0644992 0.025 0" quat="0.000796327 0 0 1">
        <inertial pos="0.0052933 -0.0512201 -0.0389842" quat="0.514518 0.0745125 -0.045741 0.853011" mass="2.3239" diaginertia="0.0208187 0.0194799 0.00432761"/>
        <joint name="opy_v05/hip_2_joint" pos="0 0 0" axis="0 1 0" limited="true" range="-3.14159 3.14159" damping="0.03" frictionloss="0.05"/>
        <geom type="mesh" rgba="0 0.4 0 1" mesh="HIP_L"/>
        <body name="opy_v05/knee_2" pos="0 -0.07885 -0.27">
          <inertial pos="-0.00882134 -3.22058e-05 -0.216025" quat="0.706362 -0.0172127 -0.0177669 0.707418" mass="0.5703" diaginertia="0.00590009 0.00582943 0.000217907"/>
          <joint name="opy_v05/knee_2_joint" pos="0 0 0" axis="0 1 0" limited="true" range="-3.14159 3.14159" damping="0.03" frictionloss="0.05"/>
          <geom type="mesh" rgba="0 0.4 0 1" mesh="KNEE"/>
          <geom name="ROBOT_FOOT_2" size="0.02" pos="0 0 -0.288398" rgba="0 0 0 0.9"/>
        </body>
      </body>
    </body>
    <body name="opy_v05/abad_3" pos="-0.223895 -0.0655252 0">
      <inertial pos="-0.0178557 -0.0014481 0.0001213" quat="0.505583 0.506923 0.494895 0.492437" mass="1.2834" diaginertia="0.00316997 0.00294345 0.000964644"/>
      <joint name="opy_v05/abad_3_joint" pos="0 0 0" axis="1 0 0" limited="true" range="-3.14159 3.14159" damping="0.03" frictionloss="0.05"/>
      <geom quat="6.34136e-07 -0.000796326 -0.000796326 -0.999999" type="mesh" rgba="0 0.4 0 1" mesh="ABDUCTION"/>
      <body name="opy_v05/hip_3" pos="-0.0644992 -0.025 0" quat="0.000796327 0 0 1">
        <inertial pos="0.0052933 0.0512201 -0.0389842" quat="0.514518 -0.0745125 0.045741 0.853011" mass="2.3239" diaginertia="0.0208187 0.0194799 0.00432761"/>
        <joint name="opy_v05/hip_3_joint" pos="0 0 0" axis="0 1 0" limited="true" range="-3.14159 3.14159" damping="0.03" frictionloss="0.05"/>
        <geom type="mesh" rgba="0 0.4 0 1" mesh="HIP_R"/>
        <body name="opy_v05/knee_3" pos="0 0.07885 -0.27">
          <inertial pos="-0.00882134 3.22058e-05 -0.216025" quat="0.707756 -0.00682173 -0.00625386 0.706396" mass="0.5703" diaginertia="0.00590009 0.00581761 0.00022972"/>
          <joint name="opy_v05/knee_3_joint" pos="0 0 0" axis="0 1 0" limited="true" range="-3.14159 3.14159" damping="0.03" frictionloss="0.05"/>
          <geom type="mesh" rgba="0 0.4 0 1" mesh="KNEE"/>
          <geom  name="ROBOT_FOOT_3" size="0.02" pos="0 0 -0.288398" rgba="0 0 0 0.9"/>
        </body>
      </body>
    </body>
    <body name="opy_v05/abad_4" pos="-0.223895 0.0655252 0">
      <inertial pos="-0.0178557 0.0014481 0.0001213" quat="0.492437 0.494895 0.506923 0.505583" mass="1.2834" diaginertia="0.00316997 0.00294345 0.000964644"/>
      <joint name="opy_v05/abad_4_joint" pos="0 0 0" axis="1 0 0" limited="true" range="-3.14159 3.14159" damping="0.03" frictionloss="0.05"/>
      <geom quat="0.000796327 0 -1 0" type="mesh" rgba="0 0.4 0 1" mesh="ABDUCTION"/>
      <body name="opy_v05/hip_4" pos="-0.0644992 0.025 0" quat="0.000796327 0 0 1">
        <inertial pos="0.0052933 -0.0512201 -0.0389842" quat="0.853011 0.045741 -0.0745125 0.514518" mass="2.3239" diaginertia="0.0208187 0.0194799 0.00432761"/>
        <joint name="opy_v05/hip_4_joint" pos="0 0 0" axis="0 1 0" limited="true" range="-3.14159 3.14159" damping="0.03" frictionloss="0.05"/>
        <geom type="mesh" rgba="0 0.4 0 1" mesh="HIP_L"/>
        <body name="opy_v05/knee_4" pos="0 -0.07885 -0.27">
          <inertial pos="-0.00882134 -3.22058e-05 -0.216025" quat="0.706396 -0.00625386 -0.00682173 0.707756" mass="0.5703" diaginertia="0.00590009 0.00581761 0.00022972"/>
          <joint name="opy_v05/knee_4_joint" pos="0 0 0" axis="0 1 0" limited="true" range="-3.14159 3.14159" damping="0.03" frictionloss="0.05"/>
          <geom type="mesh" rgba="0 0.4 0 1" mesh="KNEE"/>
          <geom name="ROBOT_FOOT_4" size="0.02" pos="0 0 -0.288398" rgba="0 0 0 0.9"/>
        </body>
      </body>
    </body>
        </body>
 <!-- <body pos="1. 0 -.015" euler = "0 0 0">
      <inertial pos="0.5 .5 0" mass= "18"/>
      <geom type="mesh" mesh = "boxx" name ="box"  rgba = ".9 0 0 1" />
    </body>
    <body pos="1.2 0 0.05" euler = "0 0 0">
      <inertial pos="0.5 .5 0" mass= "18"/>
      <geom type="mesh" mesh = "boxx" name ="box2"  rgba = ".9 0 0 1" />
    </body>
        <body pos="1.4 0 0.1" euler = "0 0 0">
      <inertial pos="0.5 .5 0" mass= "18"/>
      <geom type="mesh" mesh = "boxx" name ="box3"  rgba = ".9 0 0 1" />
    </body>
        <body pos="1.6 0 0.15" euler = "0. 0 0">
      <inertial pos="0.5 .5 0" mass= "18"/>
      <geom type="mesh" mesh = "boxx" name ="box4"  rgba = ".9 0 0 1" />
    </body>
        <body pos="1.8 0 0.2" euler = "0 0 0">
      <inertial pos="0.5 .5 0" mass= "18"/>
      <geom type="mesh" mesh = "boxx" name ="box5"  rgba = ".9 0 0 1" />
    </body>
        <body pos="2 0 0.25" euler = "-0. 0 0">
      <inertial pos="0.5 .5 0" mass= "18"/>
      <geom type="mesh" mesh = "boxx" name ="box6"  rgba = ".9 0 0 1" />
    </body>
        <body pos="2.2 0 0.3" euler = "0. 0 0">
      <inertial pos="0.5 .5 0" mass= "18"/>
      <geom type="mesh" mesh = "boxx" name ="box7"  rgba = ".9 0 0 1" />
    </body>

    <body name= "sphere1" pos="0 0 20" euler = "0 0 0" >
      <geom type="sphere"  name ="debugSphere1" contype="0" conaffinity="0" size = "0.01" rgba = ".1 1 1 1" />
      <joint type="free" />
    </body>
    <body name= "sphere2" pos="0 0 20" euler = "0 0 0" >
      <geom type="sphere"  name ="debugSphere2" contype="0" conaffinity="0" size = "0.01" rgba = ".1 1 1 1" />
      <joint type="free" />
    </body>
    <body name= "sphere3" pos="0 0 20" euler = "0 0 0" >
      <geom type="sphere"  name ="debugSphere3" contype="0" conaffinity="0" size = "0.01" rgba = ".1 1 1 1" />
      <joint type="free" />
    </body>
    <body name= "sphere4" pos="0 0 20" euler = "0 0 0" >
      <geom type="sphere"  name ="debugSphere4" contype="0" conaffinity="0" size = "0.01" rgba = ".1 1 1 1" />
      <joint type="free" />
    </body> 

    <body name= "bodysphere" pos="0 0 20" euler = "0 0 0" >
      <geom type="sphere"  name ="debugSphere5" contype="0" conaffinity="0" size = "0.2" rgba = "1 0 0 1" />
      <joint type="free" />

    </body> 
    <body name= "sphere11" pos="0 0 20" euler = "0 0 0" >
      <geom type="sphere"  name ="debugSphere11" contype="0" conaffinity="0" size = "0.01" rgba = "0 1 0 1" />
      <joint type="free" />
    </body>
    <body name= "sphere22" pos="0 0 20" euler = "0 0 0" >
      <geom type="sphere"  name ="debugSphere22" contype="0" conaffinity="0" size = "0.01" rgba ="0 1 0 1" />
      <joint type="free" />
    </body>
    <body name= "sphere33" pos="0 0 20" euler = "0 0 0" >
      <geom type="sphere"  name ="debugSphere33" contype="0" conaffinity="0" size = "0.01" rgba = "0 1 0 1" />
      <joint type="free" />
    </body>
    <body name= "sphere44" pos="0 0 20" euler = "0 0 0" >
      <geom type="sphere"  name ="debugSphere44" contype="0" conaffinity="0" size = "0.01" rgba = "0 1 0 1" />
      <joint type="free" />
    </body>  -->
  
   <body pos="1. 1 0" euler = "0 0 1.57">
      <inertial pos="0.5 .5 0" mass= "18"/>
      <geom type="mesh" mesh = "slope" name ="slope"  rgba = ".9 0 0 0.1" />
    </body>

  </worldbody>
    <actuator>
    <motor name="opy_v05/abad_1_torque" joint="opy_v05/abad_1_joint" forcelimited="true" forcerange="-125 125"/>
    <position name="opy_v05/abad_1_pos" joint="opy_v05/abad_1_joint" kp="0" />
    <velocity name="opy_v05/abad_1_vel" joint="opy_v05/abad_1_joint" kv="0" />
    <motor name="opy_v05/hip_1_joint" joint="opy_v05/hip_1_joint"  forcelimited="true" forcerange="-125 125"  />
    <position name="opy_v05/hip_1_pos" joint="opy_v05/hip_1_joint" kp="0" />
    <velocity name="opy_v05/hip_1_vel" joint="opy_v05/hip_1_joint" kv="0" />


    <motor name="opy_v05/knee_1_joint" joint="opy_v05/knee_1_joint"  forcelimited="true" forcerange="-125 125" />
    <position name="opy_v05/knee_1_pos" joint="opy_v05/knee_1_joint" kp="0" />
    <velocity name="opy_v05/knee_1_vel" joint="opy_v05/knee_1_joint" kv="0" />



    <motor name="opy_v05/abad_2_torque" joint="opy_v05/abad_2_joint" forcelimited="true" forcerange="-125 125"/>
    <position name="opy_v05/abad_2_pos" joint="opy_v05/abad_2_joint" kp="0" />
    <velocity name="opy_v05/abad_2_vel" joint="opy_v05/abad_2_joint" kv="0" />
    <motor name="opy_v05/hip_2_joint" joint="opy_v05/hip_2_joint"  forcelimited="true" forcerange="-125 125"  />
    <position name="opy_v05/hip_2_pos" joint="opy_v05/hip_2_joint" kp="0" />
    <velocity name="opy_v05/hip_2_vel" joint="opy_v05/hip_2_joint" kv="0" />


    <motor name="opy_v05/knee_2_joint" joint="opy_v05/knee_2_joint"  forcelimited="true" forcerange="-125 125" />
    <position name="opy_v05/knee_2_pos" joint="opy_v05/knee_2_joint" kp="0" />
    <velocity name="opy_v05/knee_2_vel" joint="opy_v05/knee_2_joint" kv="0" />


    <motor name="opy_v05/abad_3_torque" joint="opy_v05/abad_3_joint" forcelimited="true" forcerange="-125 125"/>
    <position name="opy_v05/abad_3_pos" joint="opy_v05/abad_3_joint" kp="0" />
    <velocity name="opy_v05/abad_3_vel" joint="opy_v05/abad_3_joint" kv="0" />

    <motor name="opy_v05/hip_3_joint" joint="opy_v05/hip_3_joint"  forcelimited="true" forcerange="-125 125"  />
    <position name="opy_v05/hip_3_pos" joint="opy_v05/hip_3_joint" kp="0" />
    <velocity name="opy_v05/hip_3_vel" joint="opy_v05/hip_3_joint" kv="0" />


    <motor name="opy_v05/knee_3_joint" joint="opy_v05/knee_3_joint"  forcelimited="true" forcerange="-125 125" />
    <position name="opy_v05/knee_3_pos" joint="opy_v05/knee_3_joint" kp="0" />
    <velocity name="opy_v05/knee_3_vel" joint="opy_v05/knee_3_joint" kv="0" />



    <motor name="opy_v05/abad_4_torque" joint="opy_v05/abad_4_joint" forcelimited="true" forcerange="-125 125"/>
    <position name="opy_v05/abad_4_pos" joint="opy_v05/abad_4_joint" kp="0" />
    <velocity name="opy_v05/abad_4_vel" joint="opy_v05/abad_4_joint" kv="0" />

    <motor name="opy_v05/hip_4_joint" joint="opy_v05/hip_4_joint"  forcelimited="true" forcerange="-125 125"  />
    <position name="opy_v05/hip_4_pos" joint="opy_v05/hip_4_joint" kp="0" />
    <velocity name="opy_v05/hip_4_vel" joint="opy_v05/hip_4_joint" kv="0" />


    <motor name="opy_v05/knee_4_joint" joint="opy_v05/knee_4_joint"  forcelimited="true" forcerange="-125 125" />
    <position name="opy_v05/knee_4_pos" joint="opy_v05/knee_4_joint" kp="0" />
    <velocity name="opy_v05/knee_4_vel" joint="opy_v05/knee_4_joint" kv="0" />


  </actuator>

  <contact>
  <pair geom1="floor" geom2="ROBOT_FOOT_1" condim="3" friction="1 1 0.005 0.0001 0.0001"  solimp =  "0.9 0.95 0.001 0.1 6" />
  <pair geom1="floor" geom2="ROBOT_FOOT_2" condim="3" friction="1 1 0.005 0.0001 0.0001" solimp =  "0.9 0.95 0.001 0.1 6"/>
  <pair geom1="floor" geom2="ROBOT_FOOT_3" condim="3" friction="1 1 0.005 0.0001 0.0001" solimp =  "0.9 0.95 0.001 0.1 6"/>
  <pair geom1="floor" geom2="ROBOT_FOOT_4" condim="3" friction="1 1 0.005 0.0001 0.0001" solimp =  "0.9 0.95 0.001 0.1 6"/>
  <!-- <pair geom1="box" geom2="ROBOT_FOOT_1" condim="3" friction="1 1 0.005 0.0001 0.0001"  solimp =  "0.9 0.95 0.001 0.1 6" />
  <pair geom1="box" geom2="ROBOT_FOOT_2" condim="3" friction="1 1 0.005 0.0001 0.0001" solimp =  "0.9 0.95 0.001 0.1 6"/>
  <pair geom1="box" geom2="ROBOT_FOOT_3" condim="3" friction="1 1 0.005 0.0001 0.0001" solimp =  "0.9 0.95 0.001 0.1 6"/>
  <pair geom1="box" geom2="ROBOT_FOOT_4" condim="3" friction="1 1 0.005 0.0001 0.0001" solimp =  "0.9 0.95 0.001 0.1 6"/> -->
  <!-- <pair geom1="obs" geom2="opy_v05/foot_1" condim="3" friction="1 1 0.005 0.0001 0.0001" solimp =  "0.9 0.95 0.001 0.1 6"/>
  <pair geom1="obs" geom2="opy_v05/foot_2" condim="3" friction="1 1 0.005 0.0001 0.0001" solimp =  "0.9 0.95 0.001 0.1 6"/>
  <pair geom1="obs" geom2="opy_v05/foot_3" condim="3" friction="1 1 0.005 0.0001 0.0001" solimp =  "0.9 0.95 0.001 0.1 6"/>
  <pair geom1="obs" geom2="opy_v05/foot_4" condim="3" friction="1 1 0.005 0.0001 0.0001" solimp =  "0.9 0.95 0.001 0.1 6"/> -->
  <exclude body1="opy_v05/hip_1" body2="opy_v05/base_link_inertia" />
  <exclude body1="opy_v05/hip_2" body2="opy_v05/base_link_inertia" />
  <exclude body1="opy_v05/hip_3" body2="opy_v05/base_link_inertia" />
  <exclude body1="opy_v05/hip_4" body2="opy_v05/base_link_inertia" />

  <exclude body1="opy_v05/knee_1" body2="opy_v05/base_link_inertia" />
  <exclude body1="opy_v05/knee_2" body2="opy_v05/base_link_inertia" />
  <exclude body1="opy_v05/knee_3" body2="opy_v05/base_link_inertia" />
  <exclude body1="opy_v05/knee_4" body2="opy_v05/base_link_inertia" />

  </contact>
  <sensor>
  <accelerometer name="acc" site="sensorsurf" />
  <gyro site="sensorsurf" />
  <framequat name="quat" objtype="body" objname="opy_v05/base_link_inertia" />
  </sensor>


</mujoco>












