<?xml version="1.0" ?>
<!-- =================================================================================== -->
<!-- |    This document was autogenerated by xacro from solo12.xacro                   | -->
<!-- |    EDITING THIS FILE BY HAND IS NOT RECOMMENDED                                 | -->
<!-- =================================================================================== -->
<!--

ASELSAN, 2023

This is a xacro file used to describe the mechanical properties of a quadruped. 

Xacro is an XML language based on URDF. It has the capability of running macros. Such as taking variables and writing functions. 
Xacro can be converted to a straightforward URDF file pretty easily. So it is advantageous to use.

This file can be used as a template for future changes in the robot. 
This file alone does not work since it refers to other Xacro files (quadruped_macros.xacro) and functions inside them.  

The document explains each property with comments (green) above them. 

As a rule of thumb, in vscode turquoise indicates variable name and orange indicates the value of the variable. 
Edit orange values only.

-->
<robot name="solo12">
  <!-- 
- custom tags. please enter the desired values if available 
gear ratios - no units
motorTauMax: maximum torque the motor can aply. Nm
batteryV: Battery Voltage, Volts
motorKT: from motor sheet
motorR: Ohms
rotorRadius: and rotorHeight in meters
RotorMass: in kg
-->
  <custom abadGearRatio="1" batteryV="24" body_height="5" hipGearRatio="1" kneeGearRatio="1" motorKT="0.095" motorR="0.272" motorTauMax="25" rotorHeight="0.0502" rotorMass="0.521" rotorRadius="0.083"/>
  <!-- robot name -->
  <!-- [kg] -->
  <!--[N] -->
  <!-- _______________________________________________________________________________ -->
  <!-- [m] -->
  <!-- [ixx ixy ixz iyy iyz izz] -->
  <!-- [m] -->
  <!-- [ixx ixy ixz iyy iyz izz] -->
  <!-- [m] -->
  <!-- [ixx ixy ixz iyy iyz izz] -->
  <!-- [m] -->
  <!-- [ixx ixy ixz iyy iyz izz] -->
  <!-- _______________________________________________________________________________ -->
  <!-- directory to file -->
  <!-- _______________________________________________________________________________ -->
  <!-- [kg] -->
  <!-- [kg] -->
  <!-- [kg] -->
  <!-- [kg] -->
  <!-- [kg] -->
  <!-- _______________________________________________________________________________ -->
  <material name="gray">
    <color rgba="0.5 0.5 0.5 1"/>
  </material>
  <material name="green">
    <color rgba="0 0.4 0 1"/>
  </material>
  <material name="black">
    <color rgba="0 0 0 0.9"/>
  </material>
  <!--link 0 -->
  <link name="solo12/base_link"> </link>
  <joint name="solo12/base_joint" type="revolute">
    <origin rpy="0 0 0" xyz="0 0 0"/>
    <parent link="solo12/base_link"/>
    <child link="solo12/base_link_inertia"/>
  </joint>
  <link name="solo12/base_link_inertia">
    <inertial>
      <origin rpy="0 0 0" xyz="0.0 0.0 0.0"/>
      <mass value="1.2512372"/>
      <!-- The base is extremely symmetrical. -->
      <inertia ixx="0.0026622" ixy="-3.684e-05" ixz="-1.716e-05" iyy="0.0138851" iyz="-9e-08" izz="0.0160537"/>
    </inertial>
    <visual>
      <origin rpy="0 0 0" xyz="0 0 0"/>
      <geometry>
        <mesh filename="package://opy-highlevel/meshes/solo12/GOVDE.stl"/>
      </geometry>
      <material name="gray"/>
    </visual>
    <collision>
      <origin rpy="0 0 0" xyz="0 0 0"/>
      <geometry>
        <mesh filename="package://opy-highlevel/meshes/solo12/GOVDE.stl"/>
      </geometry>
    </collision>
  </link>
  <joint name="solo12/abad_1_joint" type="revolute">
    <limit effort="1e3" lower="-3.141592653589793" upper="3.141592653589793" velocity="1e3"/>
    <dynamics damping="0.03" friction="0.05"/>
    <!-- abad_joint_origin -->
    <origin rpy="0 0 0" xyz="0.2141 -0.0875 0"/>
    <axis xyz="1 0 0"/>
    <parent link="solo12/base_link"/>
    <child link="solo12/abad_1"/>
  </joint>
  <link name="solo12/abad_1">
    <inertial>
      <!-- abad_link_origin -->
      <origin rpy="0 0 0" xyz="-0.0940725 0.00438935 1.384e-05"/>
      <mass value="0.14196048"/>
      <!-- [kg] -->
      <!-- abad_inertia_at_com -->
      <inertia ixx="2.802e-05" ixy="-3.687e-05" ixz="-9e-08" iyy="0.00038264" iyz="-0.0" izz="0.0003805"/>
    </inertial>
    <visual>
      <origin rpy="0 0 0" xyz="0.0195 0 0"/>
      <geometry>
        <mesh filename="package://opy-highlevel/meshes/solo12/ABDUCTION_1.stl"/>
      </geometry>
      <material name="green"/>
    </visual>
    <collision>
      <origin rpy="0 0 0" xyz="0 0 0"/>
      <geometry>
        <mesh filename="package://opy-highlevel/meshes/solo12/ABDUCTION_1.stl"/>
      </geometry>
    </collision>
  </link>
  <joint name="solo12/hip_1_joint" type="revolute">
    <limit effort="1e3" lower="-3.141592653589793" upper="3.141592653589793" velocity="1e3"/>
    <dynamics damping="0.03" friction="0.05"/>
    <!-- hip_joint_origin -->
    <origin rpy="0 0 3.14" xyz="-0.0195 -0.0145 0"/>
    <axis xyz="0 1 0"/>
    <parent link="solo12/abad_1"/>
    <child link="solo12/hip_1"/>
  </joint>
  <link name="solo12/hip_1">
    <inertial>
      <!-- hip_link_origin -->
      <origin rpy="0 0 0" xyz="-1.53e-05 -0.0176764 -0.0783823"/>
      <mass value="0.14737324"/>
      <inertia ixx="0.0004154" ixy="-0.0" ixz="1e-07" iyy="0.00041637" iyz="4.589e-05" izz="2.982e-05"/>
    </inertial>
    <visual>
      <origin rpy="0 0 3.1415" xyz="0 0 0"/>
      <geometry>
        <mesh filename="package://opy-highlevel/meshes/solo12/HIP_1.stl"/>
      </geometry>
      <material name="green"/>
    </visual>
    <collision>
      <origin rpy="0 0 3.1415" xyz="0 0 0"/>
      <geometry>
        <mesh filename="package://opy-highlevel/meshes/solo12/HIP_1.stl"/>
      </geometry>
    </collision>
  </link>
  <joint name="solo12/knee_1_joint" type="revolute">
    <!-- knee_joint_origin -->
    <origin rpy="0 0 0" xyz="0 0.03745 -0.16"/>
    <limit effort="1e3" lower="-3.141592653589793" upper="3.141592653589793" velocity="1e3"/>
    <dynamics damping="0.03" friction="0.05"/>
    <axis xyz="0 1 0"/>
    <parent link="solo12/hip_1"/>
    <child link="solo12/knee_1"/>
  </joint>
  <link name="solo12/knee_1">
    <inertial>
      <origin rpy="0 0 0" xyz="0.0 0.00776716 -0.07003876"/>
      <mass value="0.02318294"/>
      <inertia ixx="8.508e-05" ixy="-0.0" ixz="0.0" iyy="8.58e-05" iyz="-2e-06" izz="1.39e-06"/>
    </inertial>
    <visual>
      <origin rpy="0 0 3.1415" xyz="0 0 0"/>
      <geometry>
        <mesh filename="package://opy-highlevel/meshes/solo12/KNEE_1.stl"/>
      </geometry>
      <material name="green"/>
    </visual>
    <collision>
      <origin rpy="0 0 3.1415" xyz="0 0 0"/>
      <geometry>
        <mesh filename="package://opy-highlevel/meshes/solo12/KNEE_1.stl"/>
      </geometry>
    </collision>
  </link>
  <joint name="solo12/foot_1_joint" type="fixed">
    <!-- foot_joint_origin -->
    <origin rpy="0 0 0" xyz="0 0.009 -0.16"/>
    <parent link="solo12/knee_1"/>
    <child link="solo12/foot_1"/>
  </joint>
  <link name="solo12/foot_1">
    <inertial>
      <!-- foot_link_origin -->
      <origin rpy="0 0 0" xyz="0 0 0"/>
      <mass value="0.0"/>
      <!-- foot_inertia_at_com -->
      <inertia ixx="1e-08" ixy="0" ixz="0" iyy="1e-08" iyz="0" izz="1e-08"/>
    </inertial>
    <visual>
      <origin rpy="0 0 0" xyz="0 0 0"/>
      <geometry>
        <mesh filename="package://opy-highlevel/meshes/solo12/FOOT_1.stl"/>
      </geometry>
      <material name="black"/>
    </visual>
    <collision>
      <origin rpy="0 0 0" xyz="0 0 0"/>
      <geometry>
        <sphere radius="0.02"/>
      </geometry>
    </collision>
  </link>
  <joint name="solo12/abad_2_joint" type="revolute">
    <limit effort="1e3" lower="-3.141592653589793" upper="3.141592653589793" velocity="1e3"/>
    <dynamics damping="0.03" friction="0.05"/>
    <!-- abad_joint_origin -->
    <origin rpy="0 0 0" xyz="0.2141 0.0875 0"/>
    <axis xyz="1 0 0"/>
    <parent link="solo12/base_link"/>
    <child link="solo12/abad_2"/>
  </joint>
  <link name="solo12/abad_2">
    <inertial>
      <!-- abad_link_origin -->
      <origin rpy="0 0 0" xyz="-0.0940725 -0.00438935 1.384e-05"/>
      <mass value="0.14196048"/>
      <!-- [kg] -->
      <!-- abad_inertia_at_com -->
      <inertia ixx="2.802e-05" ixy="3.687e-05" ixz="-9e-08" iyy="0.00038264" iyz="0.0" izz="0.0003805"/>
    </inertial>
    <visual>
      <origin rpy="0 0 0" xyz="0.0195 0 0"/>
      <geometry>
        <mesh filename="package://opy-highlevel/meshes/solo12/ABDUCTION_2.stl"/>
      </geometry>
      <material name="green"/>
    </visual>
    <collision>
      <origin rpy="0 0 0" xyz="0 0 0"/>
      <geometry>
        <mesh filename="package://opy-highlevel/meshes/solo12/ABDUCTION_2.stl"/>
      </geometry>
    </collision>
  </link>
  <joint name="solo12/hip_2_joint" type="revolute">
    <limit effort="1e3" lower="-3.141592653589793" upper="3.141592653589793" velocity="1e3"/>
    <dynamics damping="0.03" friction="0.05"/>
    <!-- hip_joint_origin -->
    <origin rpy="0 0 3.14" xyz="-0.0195 0.0145 0"/>
    <axis xyz="0 1 0"/>
    <parent link="solo12/abad_2"/>
    <child link="solo12/hip_2"/>
  </joint>
  <link name="solo12/hip_2">
    <inertial>
      <!-- hip_link_origin -->
      <origin rpy="0 0 0" xyz="-1.53e-05 0.0176764 -0.0783823"/>
      <mass value="0.14737324"/>
      <inertia ixx="0.0004154" ixy="0.0" ixz="1e-07" iyy="0.00041637" iyz="-4.589e-05" izz="2.982e-05"/>
    </inertial>
    <visual>
      <origin rpy="0 0 3.1415" xyz="0 0 0"/>
      <geometry>
        <mesh filename="package://opy-highlevel/meshes/solo12/HIP_2.stl"/>
      </geometry>
      <material name="green"/>
    </visual>
    <collision>
      <origin rpy="0 0 3.1415" xyz="0 0 0"/>
      <geometry>
        <mesh filename="package://opy-highlevel/meshes/solo12/HIP_2.stl"/>
      </geometry>
    </collision>
  </link>
  <joint name="solo12/knee_2_joint" type="revolute">
    <!-- knee_joint_origin -->
    <origin rpy="0 0 0" xyz="0 -0.03745 -0.16"/>
    <limit effort="1e3" lower="-3.141592653589793" upper="3.141592653589793" velocity="1e3"/>
    <dynamics damping="0.03" friction="0.05"/>
    <axis xyz="0 1 0"/>
    <parent link="solo12/hip_2"/>
    <child link="solo12/knee_2"/>
  </joint>
  <link name="solo12/knee_2">
    <inertial>
      <origin rpy="0 0 0" xyz="0.0 -0.00776716 -0.07003876"/>
      <mass value="0.02318294"/>
      <inertia ixx="8.508e-05" ixy="0.0" ixz="0.0" iyy="8.58e-05" iyz="2e-06" izz="1.39e-06"/>
    </inertial>
    <visual>
      <origin rpy="0 0 3.1415" xyz="0 0 0"/>
      <geometry>
        <mesh filename="package://opy-highlevel/meshes/solo12/KNEE_2.stl"/>
      </geometry>
      <material name="green"/>
    </visual>
    <collision>
      <origin rpy="0 0 3.1415" xyz="0 0 0"/>
      <geometry>
        <mesh filename="package://opy-highlevel/meshes/solo12/KNEE_2.stl"/>
      </geometry>
    </collision>
  </link>
  <joint name="solo12/foot_2_joint" type="fixed">
    <!-- foot_joint_origin -->
    <origin rpy="0 0 0" xyz="0 -0.009 -0.16"/>
    <parent link="solo12/knee_2"/>
    <child link="solo12/foot_2"/>
  </joint>
  <link name="solo12/foot_2">
    <inertial>
      <!-- foot_link_origin -->
      <origin rpy="0 0 0" xyz="0 0 0"/>
      <mass value="0.0"/>
      <!-- foot_inertia_at_com -->
      <inertia ixx="1e-08" ixy="0" ixz="0" iyy="1e-08" iyz="0" izz="1e-08"/>
    </inertial>
    <visual>
      <origin rpy="0 0 0" xyz="0 0 0"/>
      <geometry>
        <mesh filename="package://opy-highlevel/meshes/solo12/FOOT_2.stl"/>
      </geometry>
      <material name="black"/>
    </visual>
    <collision>
      <origin rpy="0 0 0" xyz="0 0 0"/>
      <geometry>
        <sphere radius="0.02"/>
      </geometry>
    </collision>
  </link>
  <joint name="solo12/abad_3_joint" type="revolute">
    <limit effort="1e3" lower="-3.141592653589793" upper="3.141592653589793" velocity="1e3"/>
    <dynamics damping="0.03" friction="0.05"/>
    <!-- abad_joint_origin -->
    <origin rpy="0 0 0" xyz="-0.2141 -0.0875 0"/>
    <axis xyz="1 0 0"/>
    <parent link="solo12/base_link"/>
    <child link="solo12/abad_3"/>
  </joint>
  <link name="solo12/abad_3">
    <inertial>
      <!-- abad_link_origin -->
      <origin rpy="0 0 0" xyz="0.0940725 0.00438935 1.384e-05"/>
      <mass value="0.14196048"/>
      <!-- [kg] -->
      <!-- abad_inertia_at_com -->
      <inertia ixx="2.802e-05" ixy="3.687e-05" ixz="9e-08" iyy="0.00038264" iyz="-0.0" izz="0.0003805"/>
    </inertial>
    <visual>
      <origin rpy="0 0 0" xyz="-0.0195 0 0"/>
      <geometry>
        <mesh filename="package://opy-highlevel/meshes/solo12/ABDUCTION_3.stl"/>
      </geometry>
      <material name="green"/>
    </visual>
    <collision>
      <origin rpy="0 0 0" xyz="0 0 0"/>
      <geometry>
        <mesh filename="package://opy-highlevel/meshes/solo12/ABDUCTION_3.stl"/>
      </geometry>
    </collision>
  </link>
  <joint name="solo12/hip_3_joint" type="revolute">
    <limit effort="1e3" lower="-3.141592653589793" upper="3.141592653589793" velocity="1e3"/>
    <dynamics damping="0.03" friction="0.05"/>
    <!-- hip_joint_origin -->
    <origin rpy="0 0 3.14" xyz="0.0195 -0.0145 0"/>
    <axis xyz="0 1 0"/>
    <parent link="solo12/abad_3"/>
    <child link="solo12/hip_3"/>
  </joint>
  <link name="solo12/hip_3">
    <inertial>
      <!-- hip_link_origin -->
      <origin rpy="0 0 0" xyz="-1.53e-05 -0.0176764 -0.0783823"/>
      <mass value="0.14737324"/>
      <inertia ixx="0.0004154" ixy="0.0" ixz="-1e-07" iyy="0.00041637" iyz="4.589e-05" izz="2.982e-05"/>
    </inertial>
    <visual>
      <origin rpy="0 0 3.1415" xyz="0 0 0"/>
      <geometry>
        <mesh filename="package://opy-highlevel/meshes/solo12/HIP_3.stl"/>
      </geometry>
      <material name="green"/>
    </visual>
    <collision>
      <origin rpy="0 0 3.1415" xyz="0 0 0"/>
      <geometry>
        <mesh filename="package://opy-highlevel/meshes/solo12/HIP_3.stl"/>
      </geometry>
    </collision>
  </link>
  <joint name="solo12/knee_3_joint" type="revolute">
    <!-- knee_joint_origin -->
    <origin rpy="0 0 0" xyz="0 0.03745 -0.16"/>
    <limit effort="1e3" lower="-3.141592653589793" upper="3.141592653589793" velocity="1e3"/>
    <dynamics damping="0.03" friction="0.05"/>
    <axis xyz="0 1 0"/>
    <parent link="solo12/hip_3"/>
    <child link="solo12/knee_3"/>
  </joint>
  <link name="solo12/knee_3">
    <inertial>
      <origin rpy="0 0 0" xyz="0.0 0.00776716 -0.07003876"/>
      <mass value="0.02318294"/>
      <inertia ixx="8.508e-05" ixy="0.0" ixz="-0.0" iyy="8.58e-05" iyz="-2e-06" izz="1.39e-06"/>
    </inertial>
    <visual>
      <origin rpy="0 0 3.1415" xyz="0 0 0"/>
      <geometry>
        <mesh filename="package://opy-highlevel/meshes/solo12/KNEE_3.stl"/>
      </geometry>
      <material name="green"/>
    </visual>
    <collision>
      <origin rpy="0 0 3.1415" xyz="0 0 0"/>
      <geometry>
        <mesh filename="package://opy-highlevel/meshes/solo12/KNEE_3.stl"/>
      </geometry>
    </collision>
  </link>
  <joint name="solo12/foot_3_joint" type="fixed">
    <!-- foot_joint_origin -->
    <origin rpy="0 0 0" xyz="0 0.009 -0.16"/>
    <parent link="solo12/knee_3"/>
    <child link="solo12/foot_3"/>
  </joint>
  <link name="solo12/foot_3">
    <inertial>
      <!-- foot_link_origin -->
      <origin rpy="0 0 0" xyz="0 0 0"/>
      <mass value="0.0"/>
      <!-- foot_inertia_at_com -->
      <inertia ixx="1e-08" ixy="0" ixz="0" iyy="1e-08" iyz="0" izz="1e-08"/>
    </inertial>
    <visual>
      <origin rpy="0 0 0" xyz="0 0 0"/>
      <geometry>
        <mesh filename="package://opy-highlevel/meshes/solo12/FOOT_3.stl"/>
      </geometry>
      <material name="black"/>
    </visual>
    <collision>
      <origin rpy="0 0 0" xyz="0 0 0"/>
      <geometry>
        <sphere radius="0.02"/>
      </geometry>
    </collision>
  </link>
  <joint name="solo12/abad_4_joint" type="revolute">
    <limit effort="1e3" lower="-3.141592653589793" upper="3.141592653589793" velocity="1e3"/>
    <dynamics damping="0.03" friction="0.05"/>
    <!-- abad_joint_origin -->
    <origin rpy="0 0 0" xyz="-0.2141 0.0875 0"/>
    <axis xyz="1 0 0"/>
    <parent link="solo12/base_link"/>
    <child link="solo12/abad_4"/>
  </joint>
  <link name="solo12/abad_4">
    <inertial>
      <!-- abad_link_origin -->
      <origin rpy="0 0 0" xyz="0.0940725 -0.00438935 1.384e-05"/>
      <mass value="0.14196048"/>
      <!-- [kg] -->
      <!-- abad_inertia_at_com -->
      <inertia ixx="2.802e-05" ixy="-3.687e-05" ixz="9e-08" iyy="0.00038264" iyz="0.0" izz="0.0003805"/>
    </inertial>
    <visual>
      <origin rpy="0 0 0" xyz="-0.0195 0 0"/>
      <geometry>
        <mesh filename="package://opy-highlevel/meshes/solo12/ABDUCTION_4.stl"/>
      </geometry>
      <material name="green"/>
    </visual>
    <collision>
      <origin rpy="0 0 0" xyz="0 0 0"/>
      <geometry>
        <mesh filename="package://opy-highlevel/meshes/solo12/ABDUCTION_4.stl"/>
      </geometry>
    </collision>
  </link>
  <joint name="solo12/hip_4_joint" type="revolute">
    <limit effort="1e3" lower="-3.141592653589793" upper="3.141592653589793" velocity="1e3"/>
    <dynamics damping="0.03" friction="0.05"/>
    <!-- hip_joint_origin -->
    <origin rpy="0 0 3.14" xyz="0.0195 0.0145 0"/>
    <axis xyz="0 1 0"/>
    <parent link="solo12/abad_4"/>
    <child link="solo12/hip_4"/>
  </joint>
  <link name="solo12/hip_4">
    <inertial>
      <!-- hip_link_origin -->
      <origin rpy="0 0 0" xyz="-1.53e-05 0.0176764 -0.0783823"/>
      <mass value="0.14737324"/>
      <inertia ixx="0.0004154" ixy="-0.0" ixz="-1e-07" iyy="0.00041637" iyz="-4.589e-05" izz="2.982e-05"/>
    </inertial>
    <visual>
      <origin rpy="0 0 3.1415" xyz="0 0 0"/>
      <geometry>
        <mesh filename="package://opy-highlevel/meshes/solo12/HIP_4.stl"/>
      </geometry>
      <material name="green"/>
    </visual>
    <collision>
      <origin rpy="0 0 3.1415" xyz="0 0 0"/>
      <geometry>
        <mesh filename="package://opy-highlevel/meshes/solo12/HIP_4.stl"/>
      </geometry>
    </collision>
  </link>
  <joint name="solo12/knee_4_joint" type="revolute">
    <!-- knee_joint_origin -->
    <origin rpy="0 0 0" xyz="0 -0.03745 -0.16"/>
    <limit effort="1e3" lower="-3.141592653589793" upper="3.141592653589793" velocity="1e3"/>
    <dynamics damping="0.03" friction="0.05"/>
    <axis xyz="0 1 0"/>
    <parent link="solo12/hip_4"/>
    <child link="solo12/knee_4"/>
  </joint>
  <link name="solo12/knee_4">
    <inertial>
      <origin rpy="0 0 0" xyz="0.0 -0.00776716 -0.07003876"/>
      <mass value="0.02318294"/>
      <inertia ixx="8.508e-05" ixy="-0.0" ixz="-0.0" iyy="8.58e-05" iyz="2e-06" izz="1.39e-06"/>
    </inertial>
    <visual>
      <origin rpy="0 0 3.1415" xyz="0 0 0"/>
      <geometry>
        <mesh filename="package://opy-highlevel/meshes/solo12/KNEE_4.stl"/>
      </geometry>
      <material name="green"/>
    </visual>
    <collision>
      <origin rpy="0 0 3.1415" xyz="0 0 0"/>
      <geometry>
        <mesh filename="package://opy-highlevel/meshes/solo12/KNEE_4.stl"/>
      </geometry>
    </collision>
  </link>
  <joint name="solo12/foot_4_joint" type="fixed">
    <!-- foot_joint_origin -->
    <origin rpy="0 0 0" xyz="0 -0.009 -0.16"/>
    <parent link="solo12/knee_4"/>
    <child link="solo12/foot_4"/>
  </joint>
  <link name="solo12/foot_4">
    <inertial>
      <!-- foot_link_origin -->
      <origin rpy="0 0 0" xyz="0 0 0"/>
      <mass value="0.0"/>
      <!-- foot_inertia_at_com -->
      <inertia ixx="1e-08" ixy="0" ixz="0" iyy="1e-08" iyz="0" izz="1e-08"/>
    </inertial>
    <visual>
      <origin rpy="0 0 0" xyz="0 0 0"/>
      <geometry>
        <mesh filename="package://opy-highlevel/meshes/solo12/FOOT_4.stl"/>
      </geometry>
      <material name="black"/>
    </visual>
    <collision>
      <origin rpy="0 0 0" xyz="0 0 0"/>
      <geometry>
        <sphere radius="0.02"/>
      </geometry>
    </collision>
  </link>
</robot>
