<mujoco model="simple_ghost_v60">
  <compiler angle="radian" autolimits="true"/>
  <statistic meansize="0.233652" extent="1.00882" center="0 0 -0.175588"/>
    <asset>
    <!-- <hfield name="hmap" file="my_output_image.png" size="3 3 0.3 0.07"/> -->
    <texture type="skybox" builtin="gradient" rgb1="0.3 0.5 0.7" rgb2="0 0 0" width="32" height="192"/>
    <texture type="cube" name="body" builtin="flat" mark="cross" rgb1="0.8 0.6 0.4" rgb2="0.8 0.6 0.4" markrgb="1 1 1" width="127" height="762"/>
    <texture type="2d" name="grid" builtin="checker" rgb1="0.1 0.2 0.3" rgb2="0.2 0.3 0.4" width="512" height="512"/>
    <material name="body" texture="body" texuniform="true" rgba="0.8 0.6 0.4 1"/>
    <material name="grid" texture="grid" texuniform="true" reflectance="0.2"/>


  </asset>
  <worldbody>
    <geom name="floor" size="0 0 1" type="plane" material="grid" />
   
    <light name="spotlight" target="simple_ghost_v60/base_link_inertia" pos="0 -6 6" dir="0 0 -1" cutoff="30" diffuse="0.8 0.8 0.8" mode="targetbodycom"/>

    <body name="simple_ghost_v60/base_link_inertia">
      <site name="sensorsurf" pos="0 0 0" size=".005 .005 .005" rgba="0.5 0.5 0.5 1" euler="0 0 0"/>

      <joint name="simple_ghost_v60/base_joint" pos="0 0 0" type="free"/>


      
      <inertial pos="0 0 0" quat="0 0.707107 0 0.707107" mass="25" diaginertia="0.876693 0.828568 0.118542"/>
      <geom size="0.30855 0.1 0.065" type="box"/>
    <body name="simple_ghost_v60/abad_1" pos="0.30855 -0.1 0">
      <inertial pos="0.005 0 0" mass="1" diaginertia="0.0434333 0.0434333 0.0098"/>
      <joint name="simple_ghost_v60/abad_1_joint" pos="0 0 0" axis="1 0 0" range="-3.14159 3.14159" damping="0.03" frictionloss="0.05"/>
      <geom size="0.04 0.005" pos="0.005 0 0" quat="0.707388 0 -0.706825 0" type="cylinder" rgba="0 0.4 0 1"/>
      <body name="simple_ghost_v60/hip_1" pos="0.01 -0.04 0" quat="0.000796327 0 0 1">
        <inertial pos="0 0 -0.17" mass="4" diaginertia="0.0434333 0.0434333 0.0098"/>
        <joint name="simple_ghost_v60/hip_1_joint" pos="0 0 0" axis="0 1 0" range="-3.14159 3.14159" damping="0.03" frictionloss="0.05"/>
        <geom size="0.07 0.17" pos="0 0 -0.17" quat="4.63268e-05 0 0 1" type="cylinder" rgba="0 0.4 0 1"/>
        <body name="simple_ghost_v60/knee_1" pos="0 0.08024 -0.34">
          <inertial pos="0 0.00776677 -0.0700523" quat="1 -5.56931e-06 0 0" mass="2.0001" diaginertia="0.019724 0.019724 0.000900016"/>
          <joint name="simple_ghost_v60/knee_1_joint" pos="0 0 0" axis="0 1 0" range="-3.14159 3.14159" damping="0.03" frictionloss="0.05"/>
          <geom size="0.03 0.17" pos="0 0 -0.17" quat="4.63268e-05 0 0 1" type="cylinder" rgba="0 0.4 0 1"/>
          <geom size="0.04" pos="0 0 -0.34" rgba="0 0 0 0.9"/>
        </body>
      </body>
    </body>
    <body name="simple_ghost_v60/abad_2" pos="0.30855 0.1 0">
      <inertial pos="0.005 0 0" mass="1" diaginertia="0.0434333 0.0434333 0.0098"/>
      <joint name="simple_ghost_v60/abad_2_joint" pos="0 0 0" axis="1 0 0" range="-3.14159 3.14159" damping="0.03" frictionloss="0.05"/>
      <geom size="0.04 0.005" pos="0.005 0 0" quat="0.707388 0 -0.706825 0" type="cylinder" rgba="0 0.4 0 1"/>
      <body name="simple_ghost_v60/hip_2" pos="0.01 0.04 0" quat="0.000796327 0 0 1">
        <inertial pos="0 0 -0.17" mass="4" diaginertia="0.0434333 0.0434333 0.0098"/>
        <joint name="simple_ghost_v60/hip_2_joint" pos="0 0 0" axis="0 1 0" range="-3.14159 3.14159" damping="0.03" frictionloss="0.05"/>
        <geom size="0.07 0.17" pos="0 0 -0.17" quat="4.63268e-05 0 0 1" type="cylinder" rgba="0 0.4 0 1"/>
        <body name="simple_ghost_v60/knee_2" pos="0 -0.08024 -0.34">
          <inertial pos="0 -0.00776677 -0.0700523" quat="1 5.56931e-06 0 0" mass="2.0001" diaginertia="0.019724 0.019724 0.000900016"/>
          <joint name="simple_ghost_v60/knee_2_joint" pos="0 0 0" axis="0 1 0" range="-3.14159 3.14159" damping="0.03" frictionloss="0.05"/>
          <geom size="0.03 0.17" pos="0 0 -0.17" quat="4.63268e-05 0 0 1" type="cylinder" rgba="0 0.4 0 1"/>
          <geom size="0.04" pos="0 0 -0.34" rgba="0 0 0 0.9"/>
        </body>
      </body>
    </body>
    <body name="simple_ghost_v60/abad_3" pos="-0.30855 -0.1 0">
      <inertial pos="-0.005 0 0" mass="1" diaginertia="0.0434333 0.0434333 0.0098"/>
      <joint name="simple_ghost_v60/abad_3_joint" pos="0 0 0" axis="1 0 0" range="-3.14159 3.14159" damping="0.03" frictionloss="0.05"/>
      <geom size="0.04 0.005" pos="-0.005 0 0" quat="0.707388 0 -0.706825 0" type="cylinder" rgba="0 0.4 0 1"/>
      <body name="simple_ghost_v60/hip_3" pos="-0.01 -0.04 0" quat="0.000796327 0 0 1">
        <inertial pos="0 0 -0.17" mass="4" diaginertia="0.0434333 0.0434333 0.0098"/>
        <joint name="simple_ghost_v60/hip_3_joint" pos="0 0 0" axis="0 1 0" range="-3.14159 3.14159" damping="0.03" frictionloss="0.05"/>
        <geom size="0.07 0.17" pos="0 0 -0.17" quat="4.63268e-05 0 0 1" type="cylinder" rgba="0 0.4 0 1"/>
        <body name="simple_ghost_v60/knee_3" pos="0 0.08024 -0.34">
          <inertial pos="0 0.00776677 -0.0700523" quat="1 -5.56931e-06 0 0" mass="2.0001" diaginertia="0.019724 0.019724 0.000900016"/>
          <joint name="simple_ghost_v60/knee_3_joint" pos="0 0 0" axis="0 1 0" range="-3.14159 3.14159" damping="0.03" frictionloss="0.05"/>
          <geom size="0.03 0.17" pos="0 0 -0.17" quat="4.63268e-05 0 0 1" type="cylinder" rgba="0 0.4 0 1"/>
          <geom size="0.04" pos="0 0 -0.34" rgba="0 0 0 0.9"/>
        </body>
      </body>
    </body>
    <body name="simple_ghost_v60/abad_4" pos="-0.30855 0.1 0">
      <inertial pos="-0.005 0 0" mass="1" diaginertia="0.0434333 0.0434333 0.0098"/>
      <joint name="simple_ghost_v60/abad_4_joint" pos="0 0 0" axis="1 0 0" range="-3.14159 3.14159" damping="0.03" frictionloss="0.05"/>
      <geom size="0.04 0.005" pos="-0.005 0 0" quat="0.707388 0 -0.706825 0" type="cylinder" rgba="0 0.4 0 1"/>
      <body name="simple_ghost_v60/hip_4" pos="-0.01 0.04 0" quat="0.000796327 0 0 1">
        <inertial pos="0 0 -0.17" mass="4" diaginertia="0.0434333 0.0434333 0.0098"/>
        <joint name="simple_ghost_v60/hip_4_joint" pos="0 0 0" axis="0 1 0" range="-3.14159 3.14159" damping="0.03" frictionloss="0.05"/>
        <geom size="0.07 0.17" pos="0 0 -0.17" quat="4.63268e-05 0 0 1" type="cylinder" rgba="0 0.4 0 1"/>
        <body name="simple_ghost_v60/knee_4" pos="0 -0.08024 -0.34">
          <inertial pos="0 -0.00776677 -0.0700523" quat="1 5.56931e-06 0 0" mass="2.0001" diaginertia="0.019724 0.019724 0.000900016"/>
          <joint name="simple_ghost_v60/knee_4_joint" pos="0 0 0" axis="0 1 0" range="-3.14159 3.14159" damping="0.03" frictionloss="0.05"/>
          <geom size="0.03 0.17" pos="0 0 -0.17" quat="4.63268e-05 0 0 1" type="cylinder" rgba="0 0.4 0 1"/>
          <geom size="0.04" pos="0 0 -0.34" rgba="0 0 0 0.9"/>
        </body>
      </body>
    </body>
    </body>

  </worldbody>
    <actuator>
    <motor name="simple_ghost_v60/abad_1_torque" joint="simple_ghost_v60/abad_1_joint" forcelimited="true" forcerange="-125 125"/>
    <position name="simple_ghost_v60/abad_1_pos" joint="simple_ghost_v60/abad_1_joint" kp="0" />
    <velocity name="simple_ghost_v60/abad_1_vel" joint="simple_ghost_v60/abad_1_joint" kv="0" />
    <motor name="simple_ghost_v60/hip_1_joint" joint="simple_ghost_v60/hip_1_joint"  forcelimited="true" forcerange="-125 125"  />
    <position name="simple_ghost_v60/hip_1_pos" joint="simple_ghost_v60/hip_1_joint" kp="0" />
    <velocity name="simple_ghost_v60/hip_1_vel" joint="simple_ghost_v60/hip_1_joint" kv="0" />


    <motor name="simple_ghost_v60/knee_1_joint" joint="simple_ghost_v60/knee_1_joint"  forcelimited="true" forcerange="-125 125" />
    <position name="simple_ghost_v60/knee_1_pos" joint="simple_ghost_v60/knee_1_joint" kp="0" />
    <velocity name="simple_ghost_v60/knee_1_vel" joint="simple_ghost_v60/knee_1_joint" kv="0" />



    <motor name="simple_ghost_v60/abad_2_torque" joint="simple_ghost_v60/abad_2_joint" forcelimited="true" forcerange="-125 125"/>
    <position name="simple_ghost_v60/abad_2_pos" joint="simple_ghost_v60/abad_2_joint" kp="0" />
    <velocity name="simple_ghost_v60/abad_2_vel" joint="simple_ghost_v60/abad_2_joint" kv="0" />
    <motor name="simple_ghost_v60/hip_2_joint" joint="simple_ghost_v60/hip_2_joint"  forcelimited="true" forcerange="-125 125"  />
    <position name="simple_ghost_v60/hip_2_pos" joint="simple_ghost_v60/hip_2_joint" kp="0" />
    <velocity name="simple_ghost_v60/hip_2_vel" joint="simple_ghost_v60/hip_2_joint" kv="0" />


    <motor name="simple_ghost_v60/knee_2_joint" joint="simple_ghost_v60/knee_2_joint"  forcelimited="true" forcerange="-125 125" />
    <position name="simple_ghost_v60/knee_2_pos" joint="simple_ghost_v60/knee_2_joint" kp="0" />
    <velocity name="simple_ghost_v60/knee_2_vel" joint="simple_ghost_v60/knee_2_joint" kv="0" />


    <motor name="simple_ghost_v60/abad_3_torque" joint="simple_ghost_v60/abad_3_joint" forcelimited="true" forcerange="-125 125"/>
    <position name="simple_ghost_v60/abad_3_pos" joint="simple_ghost_v60/abad_3_joint" kp="0" />
    <velocity name="simple_ghost_v60/abad_3_vel" joint="simple_ghost_v60/abad_3_joint" kv="0" />

    <motor name="simple_ghost_v60/hip_3_joint" joint="simple_ghost_v60/hip_3_joint"  forcelimited="true" forcerange="-125 125"  />
    <position name="simple_ghost_v60/hip_3_pos" joint="simple_ghost_v60/hip_3_joint" kp="0" />
    <velocity name="simple_ghost_v60/hip_3_vel" joint="simple_ghost_v60/hip_3_joint" kv="0" />


    <motor name="simple_ghost_v60/knee_3_joint" joint="simple_ghost_v60/knee_3_joint"  forcelimited="true" forcerange="-125 125" />
    <position name="simple_ghost_v60/knee_3_pos" joint="simple_ghost_v60/knee_3_joint" kp="0" />
    <velocity name="simple_ghost_v60/knee_3_vel" joint="simple_ghost_v60/knee_3_joint" kv="0" />



    <motor name="simple_ghost_v60/abad_4_torque" joint="simple_ghost_v60/abad_4_joint" forcelimited="true" forcerange="-125 125"/>
    <position name="simple_ghost_v60/abad_4_pos" joint="simple_ghost_v60/abad_4_joint" kp="0" />
    <velocity name="simple_ghost_v60/abad_4_vel" joint="simple_ghost_v60/abad_4_joint" kv="0" />

    <motor name="simple_ghost_v60/hip_4_joint" joint="simple_ghost_v60/hip_4_joint"  forcelimited="true" forcerange="-125 125"  />
    <position name="simple_ghost_v60/hip_4_pos" joint="simple_ghost_v60/hip_4_joint" kp="0" />
    <velocity name="simple_ghost_v60/hip_4_vel" joint="simple_ghost_v60/hip_4_joint" kv="0" />


    <motor name="simple_ghost_v60/knee_4_joint" joint="simple_ghost_v60/knee_4_joint"  forcelimited="true" forcerange="-125 125" />
    <position name="simple_ghost_v60/knee_4_pos" joint="simple_ghost_v60/knee_4_joint" kp="0" />
    <velocity name="simple_ghost_v60/knee_4_vel" joint="simple_ghost_v60/knee_4_joint" kv="0" />


  </actuator>

  <contact>
  <!-- <pair geom1="floor" geom2="ROBOT_FOOT_1" condim="3" friction="1 1 0.005 0.0001 0.0001"  solimp =  "0.9 0.95 0.001 0.1 6" />
  <pair geom1="floor" geom2="ROBOT_FOOT_2" condim="3" friction="1 1 0.005 0.0001 0.0001" solimp =  "0.9 0.95 0.001 0.1 6"/>
  <pair geom1="floor" geom2="ROBOT_FOOT_3" condim="3" friction="1 1 0.005 0.0001 0.0001" solimp =  "0.9 0.95 0.001 0.1 6"/>
  <pair geom1="floor" geom2="ROBOT_FOOT_4" condim="3" friction="1 1 0.005 0.0001 0.0001" solimp =  "0.9 0.95 0.001 0.1 6"/>
  <pair geom1="box" geom2="ROBOT_FOOT_1" condim="3" friction="1 1 0.005 0.0001 0.0001"  solimp =  "0.9 0.95 0.001 0.1 6" />
  <pair geom1="box" geom2="ROBOT_FOOT_2" condim="3" friction="1 1 0.005 0.0001 0.0001" solimp =  "0.9 0.95 0.001 0.1 6"/>
  <pair geom1="box" geom2="ROBOT_FOOT_3" condim="3" friction="1 1 0.005 0.0001 0.0001" solimp =  "0.9 0.95 0.001 0.1 6"/>
  <pair geom1="box" geom2="ROBOT_FOOT_4" condim="3" friction="1 1 0.005 0.0001 0.0001" solimp =  "0.9 0.95 0.001 0.1 6"/> -->
  <!-- <pair geom1="obs" geom2="simple_ghost_v60/foot_1" condim="3" friction="1 1 0.005 0.0001 0.0001" solimp =  "0.9 0.95 0.001 0.1 6"/>
  <pair geom1="obs" geom2="simple_ghost_v60/foot_2" condim="3" friction="1 1 0.005 0.0001 0.0001" solimp =  "0.9 0.95 0.001 0.1 6"/>
  <pair geom1="obs" geom2="simple_ghost_v60/foot_3" condim="3" friction="1 1 0.005 0.0001 0.0001" solimp =  "0.9 0.95 0.001 0.1 6"/>
  <pair geom1="obs" geom2="simple_ghost_v60/foot_4" condim="3" friction="1 1 0.005 0.0001 0.0001" solimp =  "0.9 0.95 0.001 0.1 6"/> -->
  <exclude body1="simple_ghost_v60/hip_1" body2="simple_ghost_v60/base_link_inertia" />
  <exclude body1="simple_ghost_v60/hip_2" body2="simple_ghost_v60/base_link_inertia" />
  <exclude body1="simple_ghost_v60/hip_3" body2="simple_ghost_v60/base_link_inertia" />
  <exclude body1="simple_ghost_v60/hip_4" body2="simple_ghost_v60/base_link_inertia" />

  <exclude body1="simple_ghost_v60/knee_1" body2="simple_ghost_v60/base_link_inertia" />
  <exclude body1="simple_ghost_v60/knee_2" body2="simple_ghost_v60/base_link_inertia" />
  <exclude body1="simple_ghost_v60/knee_3" body2="simple_ghost_v60/base_link_inertia" />
  <exclude body1="simple_ghost_v60/knee_4" body2="simple_ghost_v60/base_link_inertia" />

  </contact>
  <sensor>
  <accelerometer name="acc" site="sensorsurf" />
  <gyro site="sensorsurf" />
  <framequat name="quat" objtype="body" objname="simple_ghost_v60/base_link_inertia" />
  </sensor>


</mujoco>





