<?xml version="1.0" ?>
<!-- =================================================================================== -->
<!-- |    This document was autogenerated by xacro from simple_ghost_v60.xacro         | -->
<!-- |    EDITING THIS FILE BY HAND IS NOT RECOMMENDED                                 | -->
<!-- =================================================================================== -->
<!--
This is the main Xacro file used to describe the mechanical properties of the quadruped Çomar. 

Xacro is an XML language based on URDF. It has the capability of running macros. Such as taking variables and writing functions. 
Xacro can be converted to a straightforward URDF file pretty easily. So it is advantageous to use.

This file can be used as a template for future changes in the robot. This file alone does not work since it refers to other Xacro files and functions inside them.  

The document explains each property with comments (green) above them. As a rule of  thumb turquoise indicates variable name and orange indicates the value of the variable. 
Edit orange values only.



-->
<robot name="simple_ghost_v60">
  <!-- custom tags. please enter the desired values if available 
body_height in meters. height of the body part
gear ratios - no units
motorTauMax maximum torque the motor can aply. Nm
batteryV Battery Voltage, Volts
motorKT from motor sheet
motorR Ohms
rotorRadius and rotorHeight in meters
RotorMass in kg
-->
  <custom abadGearRatio="1" batteryV="24" body_height="5" hipGearRatio="1" kneeGearRatio="1" motorKT="0.095" motorR="0.272" motorTauMax="25" rotorHeight="0.0502" rotorMass="0.521" rotorRadius="0.083"/>
  <!-- robot name -->
  <!-- directory folder containing the mesh files -->
  <!-- <xacro:property name="meshdir" value="package://opy-highlevel/meshes/solo12" />  -->
  <!-- directory to file -->
  <!-- name of the file, should not have .stl at the end -->
  <!-- <xacro:property name="body_meshfile"   value= "GOVDE" />    
  <xacro:property name="abad_meshfile"   value= "ABDUCTION" /> 
  <xacro:property name="hip_meshfile"    value= "HIP" /> 
  <xacro:property name="knee_meshfile"   value= "KNEE" /> 
  <xacro:property name="foot_meshfile"   value= "FOOT" />  -->
  <!-- [kg] -->
  <!-- [kg] -->
  <!-- [kg] -->
  <!-- [kg] -->
  <!-- [kg] -->
  <!-- [kg] -->
  <!--[N] -->
  <!-- [m] -->
  <!-- <xacro:property name="body_inertia_at_com" value="${[0.144005 0.000254013 -0.00166722
                                                                0.380679  0.00130096
                                                                          0.447682]}" />    -->
  <!-- [m] -->
  <!-- abad_com_origin: center of mass of abad link wrt abad joint origin [m] -->
  <!-- <xacro:property name="abad_com_origin"    value="${[0.011366, 0.007729, 0.0048783]}" />  -->
  <!-- abad_inertia_at_com: inertia of abad link wrt abad com origin [ixx ixy ixz iyy iyz izz] -->
  <!-- <xacro:property name="abad_inertia_at_com" value="${ [ 1220.42e-06,   4.428e-06, -0.8715e-06, 
                                                                        693.402e-06, -158.578e-06, 
                                                                              835.772e-06       ]   }" />    -->
  <!-- [m] -->
  <!-- [ixx ixy ixz iyy iyz izz] -->
  <!-- <xacro:property name="hip_inertia_at_com" value="${[5973.75e-06,  -120.436e-06, 399.58e-06, 
                                                                  5820.52e-06, -875.292e-06, 
                                                                               1518.4e-06]}" />     -->
  <!-- [m] -->
  <!-- [ixx ixy ixz iyy iyz izz] -->
  <!-- <xacro:property name="knee_inertia_at_com" value="${[1555.76e-06, 0.115e-06,    -4.2593e-06, 
                                                                  1574.68e-06,  -9.6089e-06, 
                                                                                56.2211e-06]}" />    -->
  <!-- <link name="${robot_namespace}/world_link"> </link>
    <joint name="${robot_namespace}/world_j" type="revolute">
      <limit lower="-${0}" upper="${0}" effort="1e3" velocity="1e3"/> 

      <origin xyz="0 0 0" rpy="0 0 0" />
      <parent link="${robot_namespace}/world_link" />
      <child link="${robot_namespace}/base_link" />
    </joint> -->
  <material name="gray">
    <color rgba="0.5 0.5 0.5 1"/>
  </material>
  <material name="green">
    <color rgba="0 0.4 0 1"/>
  </material>
  <material name="black">
    <color rgba="0 0 0 0.9"/>
  </material>
  <!--link 0 -->
  <link name="simple_ghost_v60/base_link"> </link>
  <joint name="simple_ghost_v60/base_joint" type="revolute">
    <origin rpy="0 0 0" xyz="0 0 0"/>
    <parent link="simple_ghost_v60/base_link"/>
    <child link="simple_ghost_v60/base_link_inertia"/>
  </joint>
  <link name="simple_ghost_v60/base_link_inertia">
    <inertial>
      <origin rpy="0 0 0" xyz="0.0 0.0 0.0"/>
      <mass value="40"/>
      <!-- The base is extremely symmetrical. -->
      <!-- Inertia tensor for a box -->
      <inertia ixx="0.18966666666666668" ixy="0.0" ixz="0.0" iyy="1.3257080333333333" iyz="0.0" izz="1.4027080333333333"/>
    </inertial>
    <visual>
      <origin rpy="0 0 0" xyz="0 0 0"/>
      <geometry>
        <box size="0.6171 0.2  0.13"/>
      </geometry>
      <material name="gray"/>
    </visual>
    <collision>
      <origin rpy="0 0 0" xyz="0 0 0"/>
      <geometry>
        <box size="0.6171 0.2  0.13"/>
      </geometry>
    </collision>
  </link>
  <joint name="simple_ghost_v60/abad_1_joint" type="revolute">
    <limit effort="1e3" lower="-3.141592653589793" upper="3.141592653589793" velocity="1e3"/>
    <dynamics damping="0.03" friction="0.05"/>
    <!-- abad_joint_origin -->
    <origin rpy="0 0 0" xyz="0.30855 -0.1 0"/>
    <axis xyz="1 0 0"/>
    <parent link="simple_ghost_v60/base_link"/>
    <child link="simple_ghost_v60/abad_1"/>
  </joint>
  <link name="simple_ghost_v60/abad_1">
    <inertial>
      <!-- abad_link_origin -->
      <origin rpy="0 0 0" xyz="0.005 0 0"/>
      <mass value="0.5"/>
      <!-- [kg] -->
      <!-- abad_inertia_at_com -->
      <!-- Inertia tensor for a cylinder -->
      <inertia ixx="0.005429166666666667" ixy="0.0" ixz="0.0" iyy="0.005429166666666667" iyz="0.0" izz="0.0012250000000000002"/>
    </inertial>
    <visual>
      <origin rpy="0 -1.57 0" xyz="0.005 0 0"/>
      <geometry>
        <cylinder length="0.01" radius="0.04"/>
      </geometry>
      <material name="green"/>
    </visual>
    <collision>
      <origin rpy="0 -1.57 0" xyz="0.005 0 0"/>
      <geometry>
        <cylinder length="0.01" radius="0.04"/>
      </geometry>
    </collision>
  </link>
  <joint name="simple_ghost_v60/hip_1_joint" type="revolute">
    <limit effort="1e3" lower="-3.141592653589793" upper="3.141592653589793" velocity="1e3"/>
    <dynamics damping="0.03" friction="0.05"/>
    <!-- hip_joint_origin -->
    <origin rpy="0 0 3.14" xyz="0.01 -0.04 0"/>
    <axis xyz="0 1 0"/>
    <parent link="simple_ghost_v60/abad_1"/>
    <child link="simple_ghost_v60/hip_1"/>
  </joint>
  <link name="simple_ghost_v60/hip_1">
    <inertial>
      <!-- hip_link_origin -->
      <origin rpy="0 0 0" xyz="0 0 -0.17"/>
      <mass value="0.5"/>
      <!-- Inertia tensor for a cylinder -->
      <inertia ixx="0.005429166666666667" ixy="0.0" ixz="0.0" iyy="0.005429166666666667" iyz="0.0" izz="0.0012250000000000002"/>
    </inertial>
    <visual>
      <origin rpy="0 0 3.1415" xyz="0 0 -0.17"/>
      <geometry>
        <cylinder length="0.34" radius="0.07"/>
      </geometry>
      <material name="green"/>
    </visual>
    <collision>
      <origin rpy="0 0 3.1415" xyz="0 0 -0.17"/>
      <geometry>
        <cylinder length="0.34" radius="0.07"/>
      </geometry>
    </collision>
  </link>
  <joint name="simple_ghost_v60/knee_1_joint" type="revolute">
    <!-- knee_joint_origin -->
    <origin rpy="0 0 0" xyz="0 0.08024 -0.34"/>
    <limit effort="1e3" lower="-3.141592653589793" upper="3.141592653589793" velocity="1e3"/>
    <dynamics damping="0.03" friction="0.05"/>
    <axis xyz="0 1 0"/>
    <parent link="simple_ghost_v60/hip_1"/>
    <child link="simple_ghost_v60/knee_1"/>
  </joint>
  <link name="simple_ghost_v60/knee_1">
    <inertial>
      <origin rpy="0 0 0" xyz="0.0 0.00776716 -0.07003876"/>
      <mass value="0.5"/>
      <!-- Inertia tensor for a cylinder -->
      <inertia ixx="0.004929166666666667" ixy="0.0" ixz="0.0" iyy="0.004929166666666667" iyz="0.0" izz="0.000225"/>
    </inertial>
    <visual>
      <origin rpy="0 0 3.1415" xyz="0 0 -0.17"/>
      <geometry>
        <cylinder length="0.34" radius="0.03"/>
      </geometry>
      <material name="green"/>
    </visual>
    <collision>
      <origin rpy="0 0 3.1415" xyz="0 0 -0.17"/>
      <geometry>
        <cylinder length="0.34" radius="0.03"/>
      </geometry>
    </collision>
  </link>
  <joint name="simple_ghost_v60/foot_1_joint" type="fixed">
    <!-- foot_joint_origin -->
    <origin rpy="0 0 0" xyz="0 0 -0.34"/>
    <parent link="simple_ghost_v60/knee_1"/>
    <child link="simple_ghost_v60/foot_1"/>
  </joint>
  <link name="simple_ghost_v60/foot_1">
    <inertial>
      <!-- foot_link_origin -->
      <origin rpy="0 0 0" xyz="0 0 0"/>
      <mass value="0.0001"/>
      <!-- foot_inertia_at_com -->
      <inertia ixx="1e-08" ixy="0" ixz="0" iyy="1e-08" iyz="0" izz="1e-08"/>
    </inertial>
    <visual>
      <origin rpy="0 0 0" xyz="0 0 0"/>
      <geometry>
        <sphere radius="0.04"/>
      </geometry>
      <material name="black"/>
    </visual>
    <collision>
      <origin rpy="0 0 0" xyz="0 0 0"/>
      <geometry>
        <sphere radius="0.04"/>
      </geometry>
    </collision>
  </link>
  <joint name="simple_ghost_v60/abad_2_joint" type="revolute">
    <limit effort="1e3" lower="-3.141592653589793" upper="3.141592653589793" velocity="1e3"/>
    <dynamics damping="0.03" friction="0.05"/>
    <!-- abad_joint_origin -->
    <origin rpy="0 0 0" xyz="0.30855 0.1 0"/>
    <axis xyz="1 0 0"/>
    <parent link="simple_ghost_v60/base_link"/>
    <child link="simple_ghost_v60/abad_2"/>
  </joint>
  <link name="simple_ghost_v60/abad_2">
    <inertial>
      <!-- abad_link_origin -->
      <origin rpy="0 0 0" xyz="0.005 0 0"/>
      <mass value="0.5"/>
      <!-- [kg] -->
      <!-- abad_inertia_at_com -->
      <!-- Inertia tensor for a cylinder -->
      <inertia ixx="0.005429166666666667" ixy="0.0" ixz="0.0" iyy="0.005429166666666667" iyz="0.0" izz="0.0012250000000000002"/>
    </inertial>
    <visual>
      <origin rpy="0 -1.57 0" xyz="0.005 0 0"/>
      <geometry>
        <cylinder length="0.01" radius="0.04"/>
      </geometry>
      <material name="green"/>
    </visual>
    <collision>
      <origin rpy="0 -1.57 0" xyz="0.005 0 0"/>
      <geometry>
        <cylinder length="0.01" radius="0.04"/>
      </geometry>
    </collision>
  </link>
  <joint name="simple_ghost_v60/hip_2_joint" type="revolute">
    <limit effort="1e3" lower="-3.141592653589793" upper="3.141592653589793" velocity="1e3"/>
    <dynamics damping="0.03" friction="0.05"/>
    <!-- hip_joint_origin -->
    <origin rpy="0 0 3.14" xyz="0.01 0.04 0"/>
    <axis xyz="0 1 0"/>
    <parent link="simple_ghost_v60/abad_2"/>
    <child link="simple_ghost_v60/hip_2"/>
  </joint>
  <link name="simple_ghost_v60/hip_2">
    <inertial>
      <!-- hip_link_origin -->
      <origin rpy="0 0 0" xyz="0 0 -0.17"/>
      <mass value="0.5"/>
      <!-- Inertia tensor for a cylinder -->
      <inertia ixx="0.005429166666666667" ixy="0.0" ixz="0.0" iyy="0.005429166666666667" iyz="0.0" izz="0.0012250000000000002"/>
    </inertial>
    <visual>
      <origin rpy="0 0 3.1415" xyz="0 0 -0.17"/>
      <geometry>
        <cylinder length="0.34" radius="0.07"/>
      </geometry>
      <material name="green"/>
    </visual>
    <collision>
      <origin rpy="0 0 3.1415" xyz="0 0 -0.17"/>
      <geometry>
        <cylinder length="0.34" radius="0.07"/>
      </geometry>
    </collision>
  </link>
  <joint name="simple_ghost_v60/knee_2_joint" type="revolute">
    <!-- knee_joint_origin -->
    <origin rpy="0 0 0" xyz="0 -0.08024 -0.34"/>
    <limit effort="1e3" lower="-3.141592653589793" upper="3.141592653589793" velocity="1e3"/>
    <dynamics damping="0.03" friction="0.05"/>
    <axis xyz="0 1 0"/>
    <parent link="simple_ghost_v60/hip_2"/>
    <child link="simple_ghost_v60/knee_2"/>
  </joint>
  <link name="simple_ghost_v60/knee_2">
    <inertial>
      <origin rpy="0 0 0" xyz="0.0 -0.00776716 -0.07003876"/>
      <mass value="0.5"/>
      <!-- Inertia tensor for a cylinder -->
      <inertia ixx="0.004929166666666667" ixy="0.0" ixz="0.0" iyy="0.004929166666666667" iyz="0.0" izz="0.000225"/>
    </inertial>
    <visual>
      <origin rpy="0 0 3.1415" xyz="0 0 -0.17"/>
      <geometry>
        <cylinder length="0.34" radius="0.03"/>
      </geometry>
      <material name="green"/>
    </visual>
    <collision>
      <origin rpy="0 0 3.1415" xyz="0 0 -0.17"/>
      <geometry>
        <cylinder length="0.34" radius="0.03"/>
      </geometry>
    </collision>
  </link>
  <joint name="simple_ghost_v60/foot_2_joint" type="fixed">
    <!-- foot_joint_origin -->
    <origin rpy="0 0 0" xyz="0 0 -0.34"/>
    <parent link="simple_ghost_v60/knee_2"/>
    <child link="simple_ghost_v60/foot_2"/>
  </joint>
  <link name="simple_ghost_v60/foot_2">
    <inertial>
      <!-- foot_link_origin -->
      <origin rpy="0 0 0" xyz="0 0 0"/>
      <mass value="0.0001"/>
      <!-- foot_inertia_at_com -->
      <inertia ixx="1e-08" ixy="0" ixz="0" iyy="1e-08" iyz="0" izz="1e-08"/>
    </inertial>
    <visual>
      <origin rpy="0 0 0" xyz="0 0 0"/>
      <geometry>
        <sphere radius="0.04"/>
      </geometry>
      <material name="black"/>
    </visual>
    <collision>
      <origin rpy="0 0 0" xyz="0 0 0"/>
      <geometry>
        <sphere radius="0.04"/>
      </geometry>
    </collision>
  </link>
  <joint name="simple_ghost_v60/abad_3_joint" type="revolute">
    <limit effort="1e3" lower="-3.141592653589793" upper="3.141592653589793" velocity="1e3"/>
    <dynamics damping="0.03" friction="0.05"/>
    <!-- abad_joint_origin -->
    <origin rpy="0 0 0" xyz="-0.30855 -0.1 0"/>
    <axis xyz="1 0 0"/>
    <parent link="simple_ghost_v60/base_link"/>
    <child link="simple_ghost_v60/abad_3"/>
  </joint>
  <link name="simple_ghost_v60/abad_3">
    <inertial>
      <!-- abad_link_origin -->
      <origin rpy="0 0 0" xyz="-0.005 0 0"/>
      <mass value="0.5"/>
      <!-- [kg] -->
      <!-- abad_inertia_at_com -->
      <!-- Inertia tensor for a cylinder -->
      <inertia ixx="0.005429166666666667" ixy="0.0" ixz="0.0" iyy="0.005429166666666667" iyz="0.0" izz="0.0012250000000000002"/>
    </inertial>
    <visual>
      <origin rpy="0 -1.57 0" xyz="-0.005 0 0"/>
      <geometry>
        <cylinder length="0.01" radius="0.04"/>
      </geometry>
      <material name="green"/>
    </visual>
    <collision>
      <origin rpy="0 -1.57 0" xyz="-0.005 0 0"/>
      <geometry>
        <cylinder length="0.01" radius="0.04"/>
      </geometry>
    </collision>
  </link>
  <joint name="simple_ghost_v60/hip_3_joint" type="revolute">
    <limit effort="1e3" lower="-3.141592653589793" upper="3.141592653589793" velocity="1e3"/>
    <dynamics damping="0.03" friction="0.05"/>
    <!-- hip_joint_origin -->
    <origin rpy="0 0 3.14" xyz="-0.01 -0.04 0"/>
    <axis xyz="0 1 0"/>
    <parent link="simple_ghost_v60/abad_3"/>
    <child link="simple_ghost_v60/hip_3"/>
  </joint>
  <link name="simple_ghost_v60/hip_3">
    <inertial>
      <!-- hip_link_origin -->
      <origin rpy="0 0 0" xyz="0 0 -0.17"/>
      <mass value="0.5"/>
      <!-- Inertia tensor for a cylinder -->
      <inertia ixx="0.005429166666666667" ixy="0.0" ixz="0.0" iyy="0.005429166666666667" iyz="0.0" izz="0.0012250000000000002"/>
    </inertial>
    <visual>
      <origin rpy="0 0 3.1415" xyz="0 0 -0.17"/>
      <geometry>
        <cylinder length="0.34" radius="0.07"/>
      </geometry>
      <material name="green"/>
    </visual>
    <collision>
      <origin rpy="0 0 3.1415" xyz="0 0 -0.17"/>
      <geometry>
        <cylinder length="0.34" radius="0.07"/>
      </geometry>
    </collision>
  </link>
  <joint name="simple_ghost_v60/knee_3_joint" type="revolute">
    <!-- knee_joint_origin -->
    <origin rpy="0 0 0" xyz="0 0.08024 -0.34"/>
    <limit effort="1e3" lower="-3.141592653589793" upper="3.141592653589793" velocity="1e3"/>
    <dynamics damping="0.03" friction="0.05"/>
    <axis xyz="0 1 0"/>
    <parent link="simple_ghost_v60/hip_3"/>
    <child link="simple_ghost_v60/knee_3"/>
  </joint>
  <link name="simple_ghost_v60/knee_3">
    <inertial>
      <origin rpy="0 0 0" xyz="0.0 0.00776716 -0.07003876"/>
      <mass value="0.5"/>
      <!-- Inertia tensor for a cylinder -->
      <inertia ixx="0.004929166666666667" ixy="0.0" ixz="0.0" iyy="0.004929166666666667" iyz="0.0" izz="0.000225"/>
    </inertial>
    <visual>
      <origin rpy="0 0 3.1415" xyz="0 0 -0.17"/>
      <geometry>
        <cylinder length="0.34" radius="0.03"/>
      </geometry>
      <material name="green"/>
    </visual>
    <collision>
      <origin rpy="0 0 3.1415" xyz="0 0 -0.17"/>
      <geometry>
        <cylinder length="0.34" radius="0.03"/>
      </geometry>
    </collision>
  </link>
  <joint name="simple_ghost_v60/foot_3_joint" type="fixed">
    <!-- foot_joint_origin -->
    <origin rpy="0 0 0" xyz="0 0 -0.34"/>
    <parent link="simple_ghost_v60/knee_3"/>
    <child link="simple_ghost_v60/foot_3"/>
  </joint>
  <link name="simple_ghost_v60/foot_3">
    <inertial>
      <!-- foot_link_origin -->
      <origin rpy="0 0 0" xyz="0 0 0"/>
      <mass value="0.0001"/>
      <!-- foot_inertia_at_com -->
      <inertia ixx="1e-08" ixy="0" ixz="0" iyy="1e-08" iyz="0" izz="1e-08"/>
    </inertial>
    <visual>
      <origin rpy="0 0 0" xyz="0 0 0"/>
      <geometry>
        <sphere radius="0.04"/>
      </geometry>
      <material name="black"/>
    </visual>
    <collision>
      <origin rpy="0 0 0" xyz="0 0 0"/>
      <geometry>
        <sphere radius="0.04"/>
      </geometry>
    </collision>
  </link>
  <joint name="simple_ghost_v60/abad_4_joint" type="revolute">
    <limit effort="1e3" lower="-3.141592653589793" upper="3.141592653589793" velocity="1e3"/>
    <dynamics damping="0.03" friction="0.05"/>
    <!-- abad_joint_origin -->
    <origin rpy="0 0 0" xyz="-0.30855 0.1 0"/>
    <axis xyz="1 0 0"/>
    <parent link="simple_ghost_v60/base_link"/>
    <child link="simple_ghost_v60/abad_4"/>
  </joint>
  <link name="simple_ghost_v60/abad_4">
    <inertial>
      <!-- abad_link_origin -->
      <origin rpy="0 0 0" xyz="-0.005 0 0"/>
      <mass value="0.5"/>
      <!-- [kg] -->
      <!-- abad_inertia_at_com -->
      <!-- Inertia tensor for a cylinder -->
      <inertia ixx="0.005429166666666667" ixy="0.0" ixz="0.0" iyy="0.005429166666666667" iyz="0.0" izz="0.0012250000000000002"/>
    </inertial>
    <visual>
      <origin rpy="0 -1.57 0" xyz="-0.005 0 0"/>
      <geometry>
        <cylinder length="0.01" radius="0.04"/>
      </geometry>
      <material name="green"/>
    </visual>
    <collision>
      <origin rpy="0 -1.57 0" xyz="-0.005 0 0"/>
      <geometry>
        <cylinder length="0.01" radius="0.04"/>
      </geometry>
    </collision>
  </link>
  <joint name="simple_ghost_v60/hip_4_joint" type="revolute">
    <limit effort="1e3" lower="-3.141592653589793" upper="3.141592653589793" velocity="1e3"/>
    <dynamics damping="0.03" friction="0.05"/>
    <!-- hip_joint_origin -->
    <origin rpy="0 0 3.14" xyz="-0.01 0.04 0"/>
    <axis xyz="0 1 0"/>
    <parent link="simple_ghost_v60/abad_4"/>
    <child link="simple_ghost_v60/hip_4"/>
  </joint>
  <link name="simple_ghost_v60/hip_4">
    <inertial>
      <!-- hip_link_origin -->
      <origin rpy="0 0 0" xyz="0 0 -0.17"/>
      <mass value="0.5"/>
      <!-- Inertia tensor for a cylinder -->
      <inertia ixx="0.005429166666666667" ixy="0.0" ixz="0.0" iyy="0.005429166666666667" iyz="0.0" izz="0.0012250000000000002"/>
    </inertial>
    <visual>
      <origin rpy="0 0 3.1415" xyz="0 0 -0.17"/>
      <geometry>
        <cylinder length="0.34" radius="0.07"/>
      </geometry>
      <material name="green"/>
    </visual>
    <collision>
      <origin rpy="0 0 3.1415" xyz="0 0 -0.17"/>
      <geometry>
        <cylinder length="0.34" radius="0.07"/>
      </geometry>
    </collision>
  </link>
  <joint name="simple_ghost_v60/knee_4_joint" type="revolute">
    <!-- knee_joint_origin -->
    <origin rpy="0 0 0" xyz="0 -0.08024 -0.34"/>
    <limit effort="1e3" lower="-3.141592653589793" upper="3.141592653589793" velocity="1e3"/>
    <dynamics damping="0.03" friction="0.05"/>
    <axis xyz="0 1 0"/>
    <parent link="simple_ghost_v60/hip_4"/>
    <child link="simple_ghost_v60/knee_4"/>
  </joint>
  <link name="simple_ghost_v60/knee_4">
    <inertial>
      <origin rpy="0 0 0" xyz="0.0 -0.00776716 -0.07003876"/>
      <mass value="0.5"/>
      <!-- Inertia tensor for a cylinder -->
      <inertia ixx="0.004929166666666667" ixy="0.0" ixz="0.0" iyy="0.004929166666666667" iyz="0.0" izz="0.000225"/>
    </inertial>
    <visual>
      <origin rpy="0 0 3.1415" xyz="0 0 -0.17"/>
      <geometry>
        <cylinder length="0.34" radius="0.03"/>
      </geometry>
      <material name="green"/>
    </visual>
    <collision>
      <origin rpy="0 0 3.1415" xyz="0 0 -0.17"/>
      <geometry>
        <cylinder length="0.34" radius="0.03"/>
      </geometry>
    </collision>
  </link>
  <joint name="simple_ghost_v60/foot_4_joint" type="fixed">
    <!-- foot_joint_origin -->
    <origin rpy="0 0 0" xyz="0 0 -0.34"/>
    <parent link="simple_ghost_v60/knee_4"/>
    <child link="simple_ghost_v60/foot_4"/>
  </joint>
  <link name="simple_ghost_v60/foot_4">
    <inertial>
      <!-- foot_link_origin -->
      <origin rpy="0 0 0" xyz="0 0 0"/>
      <mass value="0.0001"/>
      <!-- foot_inertia_at_com -->
      <inertia ixx="1e-08" ixy="0" ixz="0" iyy="1e-08" iyz="0" izz="1e-08"/>
    </inertial>
    <visual>
      <origin rpy="0 0 0" xyz="0 0 0"/>
      <geometry>
        <sphere radius="0.04"/>
      </geometry>
      <material name="black"/>
    </visual>
    <collision>
      <origin rpy="0 0 0" xyz="0 0 0"/>
      <geometry>
        <sphere radius="0.04"/>
      </geometry>
    </collision>
  </link>
</robot>
